[2024-10-31T02:41:40.716+0000] {local_task_job_runner.py:123} INFO - ::group::Pre task execution logs
[2024-10-31T02:41:40.730+0000] {taskinstance.py:2612} INFO - Dependencies all met for dep_context=non-requeueable deps ti=<TaskInstance: weather_dag.extract_data manual__2024-10-31T02:41:39.595118+00:00 [queued]>
[2024-10-31T02:41:40.736+0000] {taskinstance.py:2612} INFO - Dependencies all met for dep_context=requeueable deps ti=<TaskInstance: weather_dag.extract_data manual__2024-10-31T02:41:39.595118+00:00 [queued]>
[2024-10-31T02:41:40.736+0000] {taskinstance.py:2865} INFO - Starting attempt 1 of 2
[2024-10-31T02:41:40.746+0000] {taskinstance.py:2888} INFO - Executing <Task(BashOperator): extract_data> on 2024-10-31 02:41:39.595118+00:00
[2024-10-31T02:41:40.750+0000] {warnings.py:112} WARNING - /home/***/.local/lib/python3.12/site-packages/***/task/task_runner/standard_task_runner.py:70: DeprecationWarning: This process (pid=107) is multi-threaded, use of fork() may lead to deadlocks in the child.
  pid = os.fork()

[2024-10-31T02:41:40.752+0000] {standard_task_runner.py:104} INFO - Running: ['***', 'tasks', 'run', 'weather_dag', 'extract_data', 'manual__2024-10-31T02:41:39.595118+00:00', '--job-id', '41', '--raw', '--subdir', 'DAGS_FOLDER/Etl_weather.py', '--cfg-path', '/tmp/tmp98t9ud4m']
[2024-10-31T02:41:40.752+0000] {standard_task_runner.py:72} INFO - Started process 108 to run task
[2024-10-31T02:41:40.753+0000] {standard_task_runner.py:105} INFO - Job 41: Subtask extract_data
[2024-10-31T02:41:40.787+0000] {task_command.py:467} INFO - Running <TaskInstance: weather_dag.extract_data manual__2024-10-31T02:41:39.595118+00:00 [running]> on host 915ee6de4e26
[2024-10-31T02:41:40.847+0000] {taskinstance.py:3131} INFO - Exporting env vars: AIRFLOW_CTX_DAG_EMAIL='milo0@gmail.com' AIRFLOW_CTX_DAG_OWNER='milo' AIRFLOW_CTX_DAG_ID='weather_dag' AIRFLOW_CTX_TASK_ID='extract_data' AIRFLOW_CTX_EXECUTION_DATE='2024-10-31T02:41:39.595118+00:00' AIRFLOW_CTX_TRY_NUMBER='1' AIRFLOW_CTX_DAG_RUN_ID='manual__2024-10-31T02:41:39.595118+00:00'
[2024-10-31T02:41:40.848+0000] {taskinstance.py:731} INFO - ::endgroup::
[2024-10-31T02:41:40.858+0000] {subprocess.py:63} INFO - Tmp dir root location: /tmp
[2024-10-31T02:41:40.860+0000] {subprocess.py:75} INFO - Running command: ['/usr/bin/bash', '-c', 'python /opt/***/tmp/extract_data_api.py']
[2024-10-31T02:41:40.867+0000] {subprocess.py:86} INFO - Output:
[2024-10-31T02:41:42.790+0000] {subprocess.py:93} INFO - {'coord': {'lon': -75.5646, 'lat': 6.2529}, 'weather': [{'id': 300, 'main': 'Drizzle', 'description': 'light intensity drizzle', 'icon': '09n'}], 'base': 'stations', 'main': {'temp': 18.65, 'feels_like': 19.13, 'temp_min': 18.32, 'temp_max': 19.22, 'pressure': 1016, 'humidity': 98, 'sea_level': 1016, 'grnd_level': 807}, 'visibility': 10000, 'wind': {'speed': 8.05, 'deg': 130, 'gust': 0}, 'clouds': {'all': 75}, 'dt': 1730342164, 'sys': {'type': 2, 'id': 2084700, 'country': 'CO', 'sunrise': 1730285317, 'sunset': 1730328180}, 'timezone': -18000, 'id': 3674962, 'name': 'Medell√≠n', 'cod': 200}
[2024-10-31T02:41:42.791+0000] {subprocess.py:93} INFO - Traceback (most recent call last):
[2024-10-31T02:41:42.791+0000] {subprocess.py:93} INFO -   File "/opt/***/tmp/extract_data_api.py", line 55, in <module>
[2024-10-31T02:41:42.794+0000] {subprocess.py:93} INFO -     extract_weather_data()
[2024-10-31T02:41:42.795+0000] {subprocess.py:93} INFO -   File "/opt/***/tmp/extract_data_api.py", line 43, in extract_weather_data
[2024-10-31T02:41:42.797+0000] {subprocess.py:93} INFO -     df.to_csv("C:/Users/USUARIO/Desktop/weather_etl/tmp/weather_data.tsv", sep='\t', index=False, mode='w')
[2024-10-31T02:41:42.797+0000] {subprocess.py:93} INFO -   File "/home/***/.local/lib/python3.12/site-packages/pandas/core/generic.py", line 3902, in to_csv
[2024-10-31T02:41:42.798+0000] {subprocess.py:93} INFO -     return DataFrameRenderer(formatter).to_csv(
[2024-10-31T02:41:42.799+0000] {subprocess.py:93} INFO -            ^^^^^^^^^^^^^^^^^^^^^^^^^^^^^^^^^^^^
[2024-10-31T02:41:42.799+0000] {subprocess.py:93} INFO -   File "/home/***/.local/lib/python3.12/site-packages/pandas/io/formats/format.py", line 1152, in to_csv
[2024-10-31T02:41:42.800+0000] {subprocess.py:93} INFO -     csv_formatter.save()
[2024-10-31T02:41:42.801+0000] {subprocess.py:93} INFO -   File "/home/***/.local/lib/python3.12/site-packages/pandas/io/formats/csvs.py", line 247, in save
[2024-10-31T02:41:42.802+0000] {subprocess.py:93} INFO -     with get_handle(
[2024-10-31T02:41:42.802+0000] {subprocess.py:93} INFO -          ^^^^^^^^^^^
[2024-10-31T02:41:42.803+0000] {subprocess.py:93} INFO -   File "/home/***/.local/lib/python3.12/site-packages/pandas/io/common.py", line 739, in get_handle
[2024-10-31T02:41:42.804+0000] {subprocess.py:93} INFO -     check_parent_directory(str(handle))
[2024-10-31T02:41:42.804+0000] {subprocess.py:93} INFO -   File "/home/***/.local/lib/python3.12/site-packages/pandas/io/common.py", line 604, in check_parent_directory
[2024-10-31T02:41:42.805+0000] {subprocess.py:93} INFO -     raise OSError(rf"Cannot save file into a non-existent directory: '{parent}'")
[2024-10-31T02:41:42.806+0000] {subprocess.py:93} INFO - OSError: Cannot save file into a non-existent directory: 'C:/Users/USUARIO/Desktop/weather_etl/tmp'
[2024-10-31T02:41:42.898+0000] {subprocess.py:97} INFO - Command exited with return code 1
[2024-10-31T02:41:42.908+0000] {taskinstance.py:3310} ERROR - Task failed with exception
Traceback (most recent call last):
  File "/home/airflow/.local/lib/python3.12/site-packages/airflow/models/taskinstance.py", line 767, in _execute_task
    result = _execute_callable(context=context, **execute_callable_kwargs)
             ^^^^^^^^^^^^^^^^^^^^^^^^^^^^^^^^^^^^^^^^^^^^^^^^^^^^^^^^^^^^^
  File "/home/airflow/.local/lib/python3.12/site-packages/airflow/models/taskinstance.py", line 733, in _execute_callable
    return ExecutionCallableRunner(
           ^^^^^^^^^^^^^^^^^^^^^^^^
  File "/home/airflow/.local/lib/python3.12/site-packages/airflow/utils/operator_helpers.py", line 252, in run
    return self.func(*args, **kwargs)
           ^^^^^^^^^^^^^^^^^^^^^^^^^^
  File "/home/airflow/.local/lib/python3.12/site-packages/airflow/models/baseoperator.py", line 406, in wrapper
    return func(self, *args, **kwargs)
           ^^^^^^^^^^^^^^^^^^^^^^^^^^^
  File "/home/airflow/.local/lib/python3.12/site-packages/airflow/operators/bash.py", line 249, in execute
    raise AirflowException(
airflow.exceptions.AirflowException: Bash command failed. The command returned a non-zero exit code 1.
[2024-10-31T02:41:42.916+0000] {taskinstance.py:1225} INFO - Marking task as UP_FOR_RETRY. dag_id=weather_dag, task_id=extract_data, run_id=manual__2024-10-31T02:41:39.595118+00:00, execution_date=20241031T024139, start_date=20241031T024140, end_date=20241031T024142
[2024-10-31T02:41:42.932+0000] {taskinstance.py:340} INFO - ::group::Post task execution logs
[2024-10-31T02:41:42.934+0000] {standard_task_runner.py:124} ERROR - Failed to execute job 41 for task extract_data (Bash command failed. The command returned a non-zero exit code 1.; 108)
Traceback (most recent call last):
  File "/home/airflow/.local/lib/python3.12/site-packages/airflow/task/task_runner/standard_task_runner.py", line 117, in _start_by_fork
    ret = args.func(args, dag=self.dag)
          ^^^^^^^^^^^^^^^^^^^^^^^^^^^^^
  File "/home/airflow/.local/lib/python3.12/site-packages/airflow/cli/cli_config.py", line 49, in command
    return func(*args, **kwargs)
           ^^^^^^^^^^^^^^^^^^^^^
  File "/home/airflow/.local/lib/python3.12/site-packages/airflow/utils/cli.py", line 115, in wrapper
    return f(*args, **kwargs)
           ^^^^^^^^^^^^^^^^^^
  File "/home/airflow/.local/lib/python3.12/site-packages/airflow/cli/commands/task_command.py", line 483, in task_run
    task_return_code = _run_task_by_selected_method(args, _dag, ti)
                       ^^^^^^^^^^^^^^^^^^^^^^^^^^^^^^^^^^^^^^^^^^^^
  File "/home/airflow/.local/lib/python3.12/site-packages/airflow/cli/commands/task_command.py", line 256, in _run_task_by_selected_method
    return _run_raw_task(args, ti)
           ^^^^^^^^^^^^^^^^^^^^^^^
  File "/home/airflow/.local/lib/python3.12/site-packages/airflow/cli/commands/task_command.py", line 341, in _run_raw_task
    return ti._run_raw_task(
           ^^^^^^^^^^^^^^^^^
  File "/home/airflow/.local/lib/python3.12/site-packages/airflow/utils/session.py", line 97, in wrapper
    return func(*args, session=session, **kwargs)
           ^^^^^^^^^^^^^^^^^^^^^^^^^^^^^^^^^^^^^^
  File "/home/airflow/.local/lib/python3.12/site-packages/airflow/models/taskinstance.py", line 3004, in _run_raw_task
    return _run_raw_task(
           ^^^^^^^^^^^^^^
  File "/home/airflow/.local/lib/python3.12/site-packages/airflow/models/taskinstance.py", line 273, in _run_raw_task
    TaskInstance._execute_task_with_callbacks(
  File "/home/airflow/.local/lib/python3.12/site-packages/airflow/models/taskinstance.py", line 3158, in _execute_task_with_callbacks
    result = self._execute_task(context, task_orig)
             ^^^^^^^^^^^^^^^^^^^^^^^^^^^^^^^^^^^^^^
  File "/home/airflow/.local/lib/python3.12/site-packages/airflow/models/taskinstance.py", line 3182, in _execute_task
    return _execute_task(self, context, task_orig)
           ^^^^^^^^^^^^^^^^^^^^^^^^^^^^^^^^^^^^^^^
  File "/home/airflow/.local/lib/python3.12/site-packages/airflow/models/taskinstance.py", line 767, in _execute_task
    result = _execute_callable(context=context, **execute_callable_kwargs)
             ^^^^^^^^^^^^^^^^^^^^^^^^^^^^^^^^^^^^^^^^^^^^^^^^^^^^^^^^^^^^^
  File "/home/airflow/.local/lib/python3.12/site-packages/airflow/models/taskinstance.py", line 733, in _execute_callable
    return ExecutionCallableRunner(
           ^^^^^^^^^^^^^^^^^^^^^^^^
  File "/home/airflow/.local/lib/python3.12/site-packages/airflow/utils/operator_helpers.py", line 252, in run
    return self.func(*args, **kwargs)
           ^^^^^^^^^^^^^^^^^^^^^^^^^^
  File "/home/airflow/.local/lib/python3.12/site-packages/airflow/models/baseoperator.py", line 406, in wrapper
    return func(self, *args, **kwargs)
           ^^^^^^^^^^^^^^^^^^^^^^^^^^^
  File "/home/airflow/.local/lib/python3.12/site-packages/airflow/operators/bash.py", line 249, in execute
    raise AirflowException(
airflow.exceptions.AirflowException: Bash command failed. The command returned a non-zero exit code 1.
[2024-10-31T02:41:42.981+0000] {local_task_job_runner.py:266} INFO - Task exited with return code 1
[2024-10-31T02:41:42.992+0000] {warnings.py:112} WARNING - /home/***/.local/lib/python3.12/site-packages/***/models/baseoperator.py:1378: AirflowProviderDeprecationWarning: Call to deprecated class PostgresOperator. (Please use `***.providers.common.sql.operators.sql.SQLExecuteQueryOperator`.Also, you can provide `hook_params={'schema': <database>}`.)
  result = cls.__new__(cls)

[2024-10-31T02:41:43.002+0000] {taskinstance.py:3900} INFO - 0 downstream tasks scheduled from follow-on schedule check
[2024-10-31T02:41:43.005+0000] {local_task_job_runner.py:245} INFO - ::endgroup::
