[2024-10-31T01:41:21.108+0000] {processor.py:186} INFO - Started process (PID=58) to work on /opt/airflow/dags/Etl_weather.py
[2024-10-31T01:41:21.109+0000] {processor.py:914} INFO - Processing file /opt/airflow/dags/Etl_weather.py for tasks to queue
[2024-10-31T01:41:21.112+0000] {logging_mixin.py:190} INFO - [2024-10-31T01:41:21.111+0000] {dagbag.py:588} INFO - Filling up the DagBag from /opt/airflow/dags/Etl_weather.py
[2024-10-31T01:41:21.154+0000] {logging_mixin.py:190} INFO - [2024-10-31T01:41:21.151+0000] {dagbag.py:387} ERROR - Failed to import: /opt/airflow/dags/Etl_weather.py
Traceback (most recent call last):
  File "/home/airflow/.local/lib/python3.12/site-packages/airflow/models/dagbag.py", line 383, in parse
    loader.exec_module(new_module)
  File "<frozen importlib._bootstrap_external>", line 995, in exec_module
  File "<frozen importlib._bootstrap>", line 488, in _call_with_frames_removed
  File "/opt/airflow/dags/Etl_weather.py", line 55, in <module>
    insert_data = PostgresFileOperator(
                  ^^^^^^^^^^^^^^^^^^^^^
TypeError: 'module' object is not callable
[2024-10-31T01:41:21.157+0000] {processor.py:927} WARNING - No viable dags retrieved from /opt/airflow/dags/Etl_weather.py
[2024-10-31T01:41:21.173+0000] {processor.py:208} INFO - Processing /opt/airflow/dags/Etl_weather.py took 0.070 seconds
[2024-10-31T01:41:51.434+0000] {processor.py:186} INFO - Started process (PID=65) to work on /opt/airflow/dags/Etl_weather.py
[2024-10-31T01:41:51.435+0000] {processor.py:914} INFO - Processing file /opt/airflow/dags/Etl_weather.py for tasks to queue
[2024-10-31T01:41:51.437+0000] {logging_mixin.py:190} INFO - [2024-10-31T01:41:51.437+0000] {dagbag.py:588} INFO - Filling up the DagBag from /opt/airflow/dags/Etl_weather.py
[2024-10-31T01:41:51.464+0000] {logging_mixin.py:190} INFO - [2024-10-31T01:41:51.461+0000] {dagbag.py:387} ERROR - Failed to import: /opt/airflow/dags/Etl_weather.py
Traceback (most recent call last):
  File "/home/airflow/.local/lib/python3.12/site-packages/airflow/models/dagbag.py", line 383, in parse
    loader.exec_module(new_module)
  File "<frozen importlib._bootstrap_external>", line 995, in exec_module
  File "<frozen importlib._bootstrap>", line 488, in _call_with_frames_removed
  File "/opt/airflow/dags/Etl_weather.py", line 55, in <module>
    insert_data = PostgresFileOperator(
                  ^^^^^^^^^^^^^^^^^^^^^
TypeError: 'module' object is not callable
[2024-10-31T01:41:51.465+0000] {processor.py:927} WARNING - No viable dags retrieved from /opt/airflow/dags/Etl_weather.py
[2024-10-31T01:41:51.479+0000] {processor.py:208} INFO - Processing /opt/airflow/dags/Etl_weather.py took 0.051 seconds
[2024-10-31T01:42:21.789+0000] {processor.py:186} INFO - Started process (PID=72) to work on /opt/airflow/dags/Etl_weather.py
[2024-10-31T01:42:21.790+0000] {processor.py:914} INFO - Processing file /opt/airflow/dags/Etl_weather.py for tasks to queue
[2024-10-31T01:42:21.792+0000] {logging_mixin.py:190} INFO - [2024-10-31T01:42:21.792+0000] {dagbag.py:588} INFO - Filling up the DagBag from /opt/airflow/dags/Etl_weather.py
[2024-10-31T01:42:21.821+0000] {logging_mixin.py:190} INFO - [2024-10-31T01:42:21.817+0000] {dagbag.py:387} ERROR - Failed to import: /opt/airflow/dags/Etl_weather.py
Traceback (most recent call last):
  File "/home/airflow/.local/lib/python3.12/site-packages/airflow/models/dagbag.py", line 383, in parse
    loader.exec_module(new_module)
  File "<frozen importlib._bootstrap_external>", line 995, in exec_module
  File "<frozen importlib._bootstrap>", line 488, in _call_with_frames_removed
  File "/opt/airflow/dags/Etl_weather.py", line 55, in <module>
    insert_data = PostgresFileOperator(
                  ^^^^^^^^^^^^^^^^^^^^^
TypeError: 'module' object is not callable
[2024-10-31T01:42:21.823+0000] {processor.py:927} WARNING - No viable dags retrieved from /opt/airflow/dags/Etl_weather.py
[2024-10-31T01:42:21.839+0000] {processor.py:208} INFO - Processing /opt/airflow/dags/Etl_weather.py took 0.055 seconds
[2024-10-31T01:42:52.125+0000] {processor.py:186} INFO - Started process (PID=79) to work on /opt/airflow/dags/Etl_weather.py
[2024-10-31T01:42:52.126+0000] {processor.py:914} INFO - Processing file /opt/airflow/dags/Etl_weather.py for tasks to queue
[2024-10-31T01:42:52.128+0000] {logging_mixin.py:190} INFO - [2024-10-31T01:42:52.127+0000] {dagbag.py:588} INFO - Filling up the DagBag from /opt/airflow/dags/Etl_weather.py
[2024-10-31T01:42:52.151+0000] {logging_mixin.py:190} INFO - [2024-10-31T01:42:52.148+0000] {dagbag.py:387} ERROR - Failed to import: /opt/airflow/dags/Etl_weather.py
Traceback (most recent call last):
  File "/home/airflow/.local/lib/python3.12/site-packages/airflow/models/dagbag.py", line 383, in parse
    loader.exec_module(new_module)
  File "<frozen importlib._bootstrap_external>", line 995, in exec_module
  File "<frozen importlib._bootstrap>", line 488, in _call_with_frames_removed
  File "/opt/airflow/dags/Etl_weather.py", line 55, in <module>
    insert_data = PostgresFileOperator(
                  ^^^^^^^^^^^^^^^^^^^^^
TypeError: 'module' object is not callable
[2024-10-31T01:42:52.152+0000] {processor.py:927} WARNING - No viable dags retrieved from /opt/airflow/dags/Etl_weather.py
[2024-10-31T01:42:52.169+0000] {processor.py:208} INFO - Processing /opt/airflow/dags/Etl_weather.py took 0.049 seconds
[2024-10-31T01:43:22.431+0000] {processor.py:186} INFO - Started process (PID=92) to work on /opt/airflow/dags/Etl_weather.py
[2024-10-31T01:43:22.431+0000] {processor.py:914} INFO - Processing file /opt/airflow/dags/Etl_weather.py for tasks to queue
[2024-10-31T01:43:22.433+0000] {logging_mixin.py:190} INFO - [2024-10-31T01:43:22.433+0000] {dagbag.py:588} INFO - Filling up the DagBag from /opt/airflow/dags/Etl_weather.py
[2024-10-31T01:43:22.467+0000] {logging_mixin.py:190} INFO - [2024-10-31T01:43:22.463+0000] {dagbag.py:387} ERROR - Failed to import: /opt/airflow/dags/Etl_weather.py
Traceback (most recent call last):
  File "/home/airflow/.local/lib/python3.12/site-packages/airflow/models/dagbag.py", line 383, in parse
    loader.exec_module(new_module)
  File "<frozen importlib._bootstrap_external>", line 995, in exec_module
  File "<frozen importlib._bootstrap>", line 488, in _call_with_frames_removed
  File "/opt/airflow/dags/Etl_weather.py", line 55, in <module>
    insert_data = PostgresFileOperator(
                  ^^^^^^^^^^^^^^^^^^^^^
TypeError: 'module' object is not callable
[2024-10-31T01:43:22.468+0000] {processor.py:927} WARNING - No viable dags retrieved from /opt/airflow/dags/Etl_weather.py
[2024-10-31T01:43:22.486+0000] {processor.py:208} INFO - Processing /opt/airflow/dags/Etl_weather.py took 0.061 seconds
[2024-10-31T01:45:11.788+0000] {processor.py:186} INFO - Started process (PID=57) to work on /opt/airflow/dags/Etl_weather.py
[2024-10-31T01:45:11.789+0000] {processor.py:914} INFO - Processing file /opt/airflow/dags/Etl_weather.py for tasks to queue
[2024-10-31T01:45:11.790+0000] {logging_mixin.py:190} INFO - [2024-10-31T01:45:11.790+0000] {dagbag.py:588} INFO - Filling up the DagBag from /opt/airflow/dags/Etl_weather.py
[2024-10-31T01:45:11.826+0000] {logging_mixin.py:190} INFO - [2024-10-31T01:45:11.821+0000] {dagbag.py:387} ERROR - Failed to import: /opt/airflow/dags/Etl_weather.py
Traceback (most recent call last):
  File "/home/airflow/.local/lib/python3.12/site-packages/airflow/models/dagbag.py", line 383, in parse
    loader.exec_module(new_module)
  File "<frozen importlib._bootstrap_external>", line 995, in exec_module
  File "<frozen importlib._bootstrap>", line 488, in _call_with_frames_removed
  File "/opt/airflow/dags/Etl_weather.py", line 55, in <module>
    insert_data = PostgresFileOperator(
                  ^^^^^^^^^^^^^^^^^^^^^
TypeError: 'module' object is not callable
[2024-10-31T01:45:11.828+0000] {processor.py:927} WARNING - No viable dags retrieved from /opt/airflow/dags/Etl_weather.py
[2024-10-31T01:45:11.850+0000] {processor.py:208} INFO - Processing /opt/airflow/dags/Etl_weather.py took 0.068 seconds
[2024-10-31T01:45:42.160+0000] {processor.py:186} INFO - Started process (PID=64) to work on /opt/airflow/dags/Etl_weather.py
[2024-10-31T01:45:42.161+0000] {processor.py:914} INFO - Processing file /opt/airflow/dags/Etl_weather.py for tasks to queue
[2024-10-31T01:45:42.162+0000] {logging_mixin.py:190} INFO - [2024-10-31T01:45:42.162+0000] {dagbag.py:588} INFO - Filling up the DagBag from /opt/airflow/dags/Etl_weather.py
[2024-10-31T01:45:42.184+0000] {logging_mixin.py:190} INFO - [2024-10-31T01:45:42.183+0000] {dagbag.py:387} ERROR - Failed to import: /opt/airflow/dags/Etl_weather.py
Traceback (most recent call last):
  File "/home/airflow/.local/lib/python3.12/site-packages/airflow/models/dagbag.py", line 383, in parse
    loader.exec_module(new_module)
  File "<frozen importlib._bootstrap_external>", line 995, in exec_module
  File "<frozen importlib._bootstrap>", line 488, in _call_with_frames_removed
  File "/opt/airflow/dags/Etl_weather.py", line 55, in <module>
    insert_data = PostgresFileOperator(
                  ^^^^^^^^^^^^^^^^^^^^^
TypeError: 'module' object is not callable
[2024-10-31T01:45:42.185+0000] {processor.py:927} WARNING - No viable dags retrieved from /opt/airflow/dags/Etl_weather.py
[2024-10-31T01:45:42.199+0000] {processor.py:208} INFO - Processing /opt/airflow/dags/Etl_weather.py took 0.043 seconds
[2024-10-31T01:46:12.523+0000] {processor.py:186} INFO - Started process (PID=70) to work on /opt/airflow/dags/Etl_weather.py
[2024-10-31T01:46:12.524+0000] {processor.py:914} INFO - Processing file /opt/airflow/dags/Etl_weather.py for tasks to queue
[2024-10-31T01:46:12.526+0000] {logging_mixin.py:190} INFO - [2024-10-31T01:46:12.526+0000] {dagbag.py:588} INFO - Filling up the DagBag from /opt/airflow/dags/Etl_weather.py
[2024-10-31T01:46:12.554+0000] {logging_mixin.py:190} INFO - [2024-10-31T01:46:12.551+0000] {dagbag.py:387} ERROR - Failed to import: /opt/airflow/dags/Etl_weather.py
Traceback (most recent call last):
  File "/home/airflow/.local/lib/python3.12/site-packages/airflow/models/dagbag.py", line 383, in parse
    loader.exec_module(new_module)
  File "<frozen importlib._bootstrap_external>", line 995, in exec_module
  File "<frozen importlib._bootstrap>", line 488, in _call_with_frames_removed
  File "/opt/airflow/dags/Etl_weather.py", line 55, in <module>
    insert_data = PostgresFileOperator(
                  ^^^^^^^^^^^^^^^^^^^^^
TypeError: 'module' object is not callable
[2024-10-31T01:46:12.555+0000] {processor.py:927} WARNING - No viable dags retrieved from /opt/airflow/dags/Etl_weather.py
[2024-10-31T01:46:12.569+0000] {processor.py:208} INFO - Processing /opt/airflow/dags/Etl_weather.py took 0.050 seconds
[2024-10-31T01:46:42.837+0000] {processor.py:186} INFO - Started process (PID=77) to work on /opt/airflow/dags/Etl_weather.py
[2024-10-31T01:46:42.837+0000] {processor.py:914} INFO - Processing file /opt/airflow/dags/Etl_weather.py for tasks to queue
[2024-10-31T01:46:42.839+0000] {logging_mixin.py:190} INFO - [2024-10-31T01:46:42.839+0000] {dagbag.py:588} INFO - Filling up the DagBag from /opt/airflow/dags/Etl_weather.py
[2024-10-31T01:46:42.856+0000] {logging_mixin.py:190} INFO - [2024-10-31T01:46:42.854+0000] {dagbag.py:387} ERROR - Failed to import: /opt/airflow/dags/Etl_weather.py
Traceback (most recent call last):
  File "/home/airflow/.local/lib/python3.12/site-packages/airflow/models/dagbag.py", line 383, in parse
    loader.exec_module(new_module)
  File "<frozen importlib._bootstrap_external>", line 995, in exec_module
  File "<frozen importlib._bootstrap>", line 488, in _call_with_frames_removed
  File "/opt/airflow/dags/Etl_weather.py", line 55, in <module>
    insert_data = PostgresFileOperator(
                  ^^^^^^^^^^^^^^^^^^^^^
TypeError: 'module' object is not callable
[2024-10-31T01:46:42.857+0000] {processor.py:927} WARNING - No viable dags retrieved from /opt/airflow/dags/Etl_weather.py
[2024-10-31T01:46:42.870+0000] {processor.py:208} INFO - Processing /opt/airflow/dags/Etl_weather.py took 0.037 seconds
[2024-10-31T01:47:13.146+0000] {processor.py:186} INFO - Started process (PID=90) to work on /opt/airflow/dags/Etl_weather.py
[2024-10-31T01:47:13.147+0000] {processor.py:914} INFO - Processing file /opt/airflow/dags/Etl_weather.py for tasks to queue
[2024-10-31T01:47:13.150+0000] {logging_mixin.py:190} INFO - [2024-10-31T01:47:13.149+0000] {dagbag.py:588} INFO - Filling up the DagBag from /opt/airflow/dags/Etl_weather.py
[2024-10-31T01:47:13.173+0000] {logging_mixin.py:190} INFO - [2024-10-31T01:47:13.171+0000] {dagbag.py:387} ERROR - Failed to import: /opt/airflow/dags/Etl_weather.py
Traceback (most recent call last):
  File "/home/airflow/.local/lib/python3.12/site-packages/airflow/models/dagbag.py", line 383, in parse
    loader.exec_module(new_module)
  File "<frozen importlib._bootstrap_external>", line 995, in exec_module
  File "<frozen importlib._bootstrap>", line 488, in _call_with_frames_removed
  File "/opt/airflow/dags/Etl_weather.py", line 55, in <module>
    insert_data = PostgresFileOperator(
                  ^^^^^^^^^^^^^^^^^^^^^
TypeError: 'module' object is not callable
[2024-10-31T01:47:13.174+0000] {processor.py:927} WARNING - No viable dags retrieved from /opt/airflow/dags/Etl_weather.py
[2024-10-31T01:47:13.190+0000] {processor.py:208} INFO - Processing /opt/airflow/dags/Etl_weather.py took 0.050 seconds
[2024-10-31T01:47:43.558+0000] {processor.py:186} INFO - Started process (PID=97) to work on /opt/airflow/dags/Etl_weather.py
[2024-10-31T01:47:43.559+0000] {processor.py:914} INFO - Processing file /opt/airflow/dags/Etl_weather.py for tasks to queue
[2024-10-31T01:47:43.561+0000] {logging_mixin.py:190} INFO - [2024-10-31T01:47:43.561+0000] {dagbag.py:588} INFO - Filling up the DagBag from /opt/airflow/dags/Etl_weather.py
[2024-10-31T01:47:43.585+0000] {logging_mixin.py:190} INFO - [2024-10-31T01:47:43.583+0000] {dagbag.py:387} ERROR - Failed to import: /opt/airflow/dags/Etl_weather.py
Traceback (most recent call last):
  File "/home/airflow/.local/lib/python3.12/site-packages/airflow/models/dagbag.py", line 383, in parse
    loader.exec_module(new_module)
  File "<frozen importlib._bootstrap_external>", line 995, in exec_module
  File "<frozen importlib._bootstrap>", line 488, in _call_with_frames_removed
  File "/opt/airflow/dags/Etl_weather.py", line 55, in <module>
    insert_data = PostgresFileOperator(
                  ^^^^^^^^^^^^^^^^^^^^^
TypeError: 'module' object is not callable
[2024-10-31T01:47:43.586+0000] {processor.py:927} WARNING - No viable dags retrieved from /opt/airflow/dags/Etl_weather.py
[2024-10-31T01:47:43.600+0000] {processor.py:208} INFO - Processing /opt/airflow/dags/Etl_weather.py took 0.046 seconds
[2024-10-31T01:48:28.417+0000] {processor.py:186} INFO - Started process (PID=51) to work on /opt/airflow/dags/Etl_weather.py
[2024-10-31T01:48:28.418+0000] {processor.py:914} INFO - Processing file /opt/airflow/dags/Etl_weather.py for tasks to queue
[2024-10-31T01:48:28.420+0000] {logging_mixin.py:190} INFO - [2024-10-31T01:48:28.420+0000] {dagbag.py:588} INFO - Filling up the DagBag from /opt/airflow/dags/Etl_weather.py
[2024-10-31T01:48:28.446+0000] {logging_mixin.py:190} INFO - [2024-10-31T01:48:28.443+0000] {dagbag.py:387} ERROR - Failed to import: /opt/airflow/dags/Etl_weather.py
Traceback (most recent call last):
  File "/home/airflow/.local/lib/python3.12/site-packages/airflow/models/dagbag.py", line 383, in parse
    loader.exec_module(new_module)
  File "<frozen importlib._bootstrap_external>", line 995, in exec_module
  File "<frozen importlib._bootstrap>", line 488, in _call_with_frames_removed
  File "/opt/airflow/dags/Etl_weather.py", line 55, in <module>
    insert_data = PostgresFileOperator(
                  ^^^^^^^^^^^^^^^^^^^^^
TypeError: 'module' object is not callable
[2024-10-31T01:48:28.447+0000] {processor.py:927} WARNING - No viable dags retrieved from /opt/airflow/dags/Etl_weather.py
[2024-10-31T01:48:28.461+0000] {processor.py:208} INFO - Processing /opt/airflow/dags/Etl_weather.py took 0.049 seconds
[2024-10-31T01:48:58.762+0000] {processor.py:186} INFO - Started process (PID=58) to work on /opt/airflow/dags/Etl_weather.py
[2024-10-31T01:48:58.762+0000] {processor.py:914} INFO - Processing file /opt/airflow/dags/Etl_weather.py for tasks to queue
[2024-10-31T01:48:58.764+0000] {logging_mixin.py:190} INFO - [2024-10-31T01:48:58.764+0000] {dagbag.py:588} INFO - Filling up the DagBag from /opt/airflow/dags/Etl_weather.py
[2024-10-31T01:48:58.790+0000] {logging_mixin.py:190} INFO - [2024-10-31T01:48:58.788+0000] {dagbag.py:387} ERROR - Failed to import: /opt/airflow/dags/Etl_weather.py
Traceback (most recent call last):
  File "/home/airflow/.local/lib/python3.12/site-packages/airflow/models/dagbag.py", line 383, in parse
    loader.exec_module(new_module)
  File "<frozen importlib._bootstrap_external>", line 995, in exec_module
  File "<frozen importlib._bootstrap>", line 488, in _call_with_frames_removed
  File "/opt/airflow/dags/Etl_weather.py", line 55, in <module>
    insert_data = PostgresFileOperator(
                  ^^^^^^^^^^^^^^^^^^^^^
TypeError: 'module' object is not callable
[2024-10-31T01:48:58.791+0000] {processor.py:927} WARNING - No viable dags retrieved from /opt/airflow/dags/Etl_weather.py
[2024-10-31T01:48:58.806+0000] {processor.py:208} INFO - Processing /opt/airflow/dags/Etl_weather.py took 0.048 seconds
[2024-10-31T01:49:29.075+0000] {processor.py:186} INFO - Started process (PID=65) to work on /opt/airflow/dags/Etl_weather.py
[2024-10-31T01:49:29.076+0000] {processor.py:914} INFO - Processing file /opt/airflow/dags/Etl_weather.py for tasks to queue
[2024-10-31T01:49:29.077+0000] {logging_mixin.py:190} INFO - [2024-10-31T01:49:29.077+0000] {dagbag.py:588} INFO - Filling up the DagBag from /opt/airflow/dags/Etl_weather.py
[2024-10-31T01:49:29.098+0000] {logging_mixin.py:190} INFO - [2024-10-31T01:49:29.096+0000] {dagbag.py:387} ERROR - Failed to import: /opt/airflow/dags/Etl_weather.py
Traceback (most recent call last):
  File "/home/airflow/.local/lib/python3.12/site-packages/airflow/models/dagbag.py", line 383, in parse
    loader.exec_module(new_module)
  File "<frozen importlib._bootstrap_external>", line 995, in exec_module
  File "<frozen importlib._bootstrap>", line 488, in _call_with_frames_removed
  File "/opt/airflow/dags/Etl_weather.py", line 55, in <module>
    insert_data = PostgresFileOperator(
                  ^^^^^^^^^^^^^^^^^^^^^
TypeError: 'module' object is not callable
[2024-10-31T01:49:29.099+0000] {processor.py:927} WARNING - No viable dags retrieved from /opt/airflow/dags/Etl_weather.py
[2024-10-31T01:49:29.113+0000] {processor.py:208} INFO - Processing /opt/airflow/dags/Etl_weather.py took 0.043 seconds
[2024-10-31T01:49:59.426+0000] {processor.py:186} INFO - Started process (PID=72) to work on /opt/airflow/dags/Etl_weather.py
[2024-10-31T01:49:59.426+0000] {processor.py:914} INFO - Processing file /opt/airflow/dags/Etl_weather.py for tasks to queue
[2024-10-31T01:49:59.428+0000] {logging_mixin.py:190} INFO - [2024-10-31T01:49:59.428+0000] {dagbag.py:588} INFO - Filling up the DagBag from /opt/airflow/dags/Etl_weather.py
[2024-10-31T01:49:59.445+0000] {logging_mixin.py:190} INFO - [2024-10-31T01:49:59.443+0000] {dagbag.py:387} ERROR - Failed to import: /opt/airflow/dags/Etl_weather.py
Traceback (most recent call last):
  File "/home/airflow/.local/lib/python3.12/site-packages/airflow/models/dagbag.py", line 383, in parse
    loader.exec_module(new_module)
  File "<frozen importlib._bootstrap_external>", line 995, in exec_module
  File "<frozen importlib._bootstrap>", line 488, in _call_with_frames_removed
  File "/opt/airflow/dags/Etl_weather.py", line 55, in <module>
    insert_data = PostgresFileOperator(
                  ^^^^^^^^^^^^^^^^^^^^^
TypeError: 'module' object is not callable
[2024-10-31T01:49:59.446+0000] {processor.py:927} WARNING - No viable dags retrieved from /opt/airflow/dags/Etl_weather.py
[2024-10-31T01:49:59.459+0000] {processor.py:208} INFO - Processing /opt/airflow/dags/Etl_weather.py took 0.037 seconds
[2024-10-31T01:50:29.724+0000] {processor.py:186} INFO - Started process (PID=79) to work on /opt/airflow/dags/Etl_weather.py
[2024-10-31T01:50:29.725+0000] {processor.py:914} INFO - Processing file /opt/airflow/dags/Etl_weather.py for tasks to queue
[2024-10-31T01:50:29.727+0000] {logging_mixin.py:190} INFO - [2024-10-31T01:50:29.727+0000] {dagbag.py:588} INFO - Filling up the DagBag from /opt/airflow/dags/Etl_weather.py
[2024-10-31T01:50:29.750+0000] {logging_mixin.py:190} INFO - [2024-10-31T01:50:29.748+0000] {dagbag.py:387} ERROR - Failed to import: /opt/airflow/dags/Etl_weather.py
Traceback (most recent call last):
  File "/home/airflow/.local/lib/python3.12/site-packages/airflow/models/dagbag.py", line 383, in parse
    loader.exec_module(new_module)
  File "<frozen importlib._bootstrap_external>", line 995, in exec_module
  File "<frozen importlib._bootstrap>", line 488, in _call_with_frames_removed
  File "/opt/airflow/dags/Etl_weather.py", line 55, in <module>
    insert_data = PostgresFileOperator(
                  ^^^^^^^^^^^^^^^^^^^^^
TypeError: 'module' object is not callable
[2024-10-31T01:50:29.751+0000] {processor.py:927} WARNING - No viable dags retrieved from /opt/airflow/dags/Etl_weather.py
[2024-10-31T01:50:29.769+0000] {processor.py:208} INFO - Processing /opt/airflow/dags/Etl_weather.py took 0.050 seconds
[2024-10-31T01:51:00.057+0000] {processor.py:186} INFO - Started process (PID=92) to work on /opt/airflow/dags/Etl_weather.py
[2024-10-31T01:51:00.058+0000] {processor.py:914} INFO - Processing file /opt/airflow/dags/Etl_weather.py for tasks to queue
[2024-10-31T01:51:00.060+0000] {logging_mixin.py:190} INFO - [2024-10-31T01:51:00.060+0000] {dagbag.py:588} INFO - Filling up the DagBag from /opt/airflow/dags/Etl_weather.py
[2024-10-31T01:51:00.081+0000] {logging_mixin.py:190} INFO - [2024-10-31T01:51:00.078+0000] {dagbag.py:387} ERROR - Failed to import: /opt/airflow/dags/Etl_weather.py
Traceback (most recent call last):
  File "/home/airflow/.local/lib/python3.12/site-packages/airflow/models/dagbag.py", line 383, in parse
    loader.exec_module(new_module)
  File "<frozen importlib._bootstrap_external>", line 995, in exec_module
  File "<frozen importlib._bootstrap>", line 488, in _call_with_frames_removed
  File "/opt/airflow/dags/Etl_weather.py", line 55, in <module>
    insert_data = PostgresFileOperator(
                  ^^^^^^^^^^^^^^^^^^^^^
TypeError: 'module' object is not callable
[2024-10-31T01:51:00.081+0000] {processor.py:927} WARNING - No viable dags retrieved from /opt/airflow/dags/Etl_weather.py
[2024-10-31T01:51:00.097+0000] {processor.py:208} INFO - Processing /opt/airflow/dags/Etl_weather.py took 0.044 seconds
[2024-10-31T01:51:30.427+0000] {processor.py:186} INFO - Started process (PID=99) to work on /opt/airflow/dags/Etl_weather.py
[2024-10-31T01:51:30.428+0000] {processor.py:914} INFO - Processing file /opt/airflow/dags/Etl_weather.py for tasks to queue
[2024-10-31T01:51:30.430+0000] {logging_mixin.py:190} INFO - [2024-10-31T01:51:30.429+0000] {dagbag.py:588} INFO - Filling up the DagBag from /opt/airflow/dags/Etl_weather.py
[2024-10-31T01:51:30.462+0000] {logging_mixin.py:190} INFO - [2024-10-31T01:51:30.460+0000] {dagbag.py:387} ERROR - Failed to import: /opt/airflow/dags/Etl_weather.py
Traceback (most recent call last):
  File "/home/airflow/.local/lib/python3.12/site-packages/airflow/models/dagbag.py", line 383, in parse
    loader.exec_module(new_module)
  File "<frozen importlib._bootstrap_external>", line 995, in exec_module
  File "<frozen importlib._bootstrap>", line 488, in _call_with_frames_removed
  File "/opt/airflow/dags/Etl_weather.py", line 55, in <module>
    insert_data = PostgresFileOperator(
                  ^^^^^^^^^^^^^^^^^^^^^
TypeError: 'module' object is not callable
[2024-10-31T01:51:30.462+0000] {processor.py:927} WARNING - No viable dags retrieved from /opt/airflow/dags/Etl_weather.py
[2024-10-31T01:51:30.494+0000] {processor.py:208} INFO - Processing /opt/airflow/dags/Etl_weather.py took 0.070 seconds
[2024-10-31T01:52:00.736+0000] {processor.py:186} INFO - Started process (PID=106) to work on /opt/airflow/dags/Etl_weather.py
[2024-10-31T01:52:00.737+0000] {processor.py:914} INFO - Processing file /opt/airflow/dags/Etl_weather.py for tasks to queue
[2024-10-31T01:52:00.739+0000] {logging_mixin.py:190} INFO - [2024-10-31T01:52:00.738+0000] {dagbag.py:588} INFO - Filling up the DagBag from /opt/airflow/dags/Etl_weather.py
[2024-10-31T01:52:00.769+0000] {logging_mixin.py:190} INFO - [2024-10-31T01:52:00.766+0000] {dagbag.py:387} ERROR - Failed to import: /opt/airflow/dags/Etl_weather.py
Traceback (most recent call last):
  File "/home/airflow/.local/lib/python3.12/site-packages/airflow/models/dagbag.py", line 383, in parse
    loader.exec_module(new_module)
  File "<frozen importlib._bootstrap_external>", line 995, in exec_module
  File "<frozen importlib._bootstrap>", line 488, in _call_with_frames_removed
  File "/opt/airflow/dags/Etl_weather.py", line 55, in <module>
    insert_data = PostgresFileOperator(
                  ^^^^^^^^^^^^^^^^^^^^^
TypeError: 'module' object is not callable
[2024-10-31T01:52:00.770+0000] {processor.py:927} WARNING - No viable dags retrieved from /opt/airflow/dags/Etl_weather.py
[2024-10-31T01:52:00.785+0000] {processor.py:208} INFO - Processing /opt/airflow/dags/Etl_weather.py took 0.053 seconds
[2024-10-31T01:52:31.122+0000] {processor.py:186} INFO - Started process (PID=113) to work on /opt/airflow/dags/Etl_weather.py
[2024-10-31T01:52:31.123+0000] {processor.py:914} INFO - Processing file /opt/airflow/dags/Etl_weather.py for tasks to queue
[2024-10-31T01:52:31.125+0000] {logging_mixin.py:190} INFO - [2024-10-31T01:52:31.124+0000] {dagbag.py:588} INFO - Filling up the DagBag from /opt/airflow/dags/Etl_weather.py
[2024-10-31T01:52:31.153+0000] {logging_mixin.py:190} INFO - [2024-10-31T01:52:31.150+0000] {dagbag.py:387} ERROR - Failed to import: /opt/airflow/dags/Etl_weather.py
Traceback (most recent call last):
  File "/home/airflow/.local/lib/python3.12/site-packages/airflow/models/dagbag.py", line 383, in parse
    loader.exec_module(new_module)
  File "<frozen importlib._bootstrap_external>", line 995, in exec_module
  File "<frozen importlib._bootstrap>", line 488, in _call_with_frames_removed
  File "/opt/airflow/dags/Etl_weather.py", line 55, in <module>
    insert_data = PostgresFileOperator(
                  ^^^^^^^^^^^^^^^^^^^^^
TypeError: 'module' object is not callable
[2024-10-31T01:52:31.155+0000] {processor.py:927} WARNING - No viable dags retrieved from /opt/airflow/dags/Etl_weather.py
[2024-10-31T01:52:31.170+0000] {processor.py:208} INFO - Processing /opt/airflow/dags/Etl_weather.py took 0.052 seconds
[2024-10-31T01:53:01.446+0000] {processor.py:186} INFO - Started process (PID=120) to work on /opt/airflow/dags/Etl_weather.py
[2024-10-31T01:53:01.446+0000] {processor.py:914} INFO - Processing file /opt/airflow/dags/Etl_weather.py for tasks to queue
[2024-10-31T01:53:01.449+0000] {logging_mixin.py:190} INFO - [2024-10-31T01:53:01.449+0000] {dagbag.py:588} INFO - Filling up the DagBag from /opt/airflow/dags/Etl_weather.py
[2024-10-31T01:53:01.479+0000] {logging_mixin.py:190} INFO - [2024-10-31T01:53:01.476+0000] {dagbag.py:387} ERROR - Failed to import: /opt/airflow/dags/Etl_weather.py
Traceback (most recent call last):
  File "/home/airflow/.local/lib/python3.12/site-packages/airflow/models/dagbag.py", line 383, in parse
    loader.exec_module(new_module)
  File "<frozen importlib._bootstrap_external>", line 995, in exec_module
  File "<frozen importlib._bootstrap>", line 488, in _call_with_frames_removed
  File "/opt/airflow/dags/Etl_weather.py", line 55, in <module>
    insert_data = PostgresFileOperator(
                  ^^^^^^^^^^^^^^^^^^^^^
TypeError: 'module' object is not callable
[2024-10-31T01:53:01.480+0000] {processor.py:927} WARNING - No viable dags retrieved from /opt/airflow/dags/Etl_weather.py
[2024-10-31T01:53:01.491+0000] {processor.py:208} INFO - Processing /opt/airflow/dags/Etl_weather.py took 0.050 seconds
[2024-10-31T01:53:31.816+0000] {processor.py:186} INFO - Started process (PID=127) to work on /opt/airflow/dags/Etl_weather.py
[2024-10-31T01:53:31.817+0000] {processor.py:914} INFO - Processing file /opt/airflow/dags/Etl_weather.py for tasks to queue
[2024-10-31T01:53:31.819+0000] {logging_mixin.py:190} INFO - [2024-10-31T01:53:31.819+0000] {dagbag.py:588} INFO - Filling up the DagBag from /opt/airflow/dags/Etl_weather.py
[2024-10-31T01:53:31.845+0000] {logging_mixin.py:190} INFO - [2024-10-31T01:53:31.842+0000] {dagbag.py:387} ERROR - Failed to import: /opt/airflow/dags/Etl_weather.py
Traceback (most recent call last):
  File "/home/airflow/.local/lib/python3.12/site-packages/airflow/models/dagbag.py", line 383, in parse
    loader.exec_module(new_module)
  File "<frozen importlib._bootstrap_external>", line 995, in exec_module
  File "<frozen importlib._bootstrap>", line 488, in _call_with_frames_removed
  File "/opt/airflow/dags/Etl_weather.py", line 55, in <module>
    insert_data = PostgresFileOperator(
                  ^^^^^^^^^^^^^^^^^^^^^
TypeError: 'module' object is not callable
[2024-10-31T01:53:31.847+0000] {processor.py:927} WARNING - No viable dags retrieved from /opt/airflow/dags/Etl_weather.py
[2024-10-31T01:53:31.862+0000] {processor.py:208} INFO - Processing /opt/airflow/dags/Etl_weather.py took 0.050 seconds
[2024-10-31T01:54:16.356+0000] {processor.py:186} INFO - Started process (PID=51) to work on /opt/airflow/dags/Etl_weather.py
[2024-10-31T01:54:16.357+0000] {processor.py:914} INFO - Processing file /opt/airflow/dags/Etl_weather.py for tasks to queue
[2024-10-31T01:54:16.359+0000] {logging_mixin.py:190} INFO - [2024-10-31T01:54:16.359+0000] {dagbag.py:588} INFO - Filling up the DagBag from /opt/airflow/dags/Etl_weather.py
[2024-10-31T01:54:16.387+0000] {logging_mixin.py:190} INFO - [2024-10-31T01:54:16.384+0000] {dagbag.py:387} ERROR - Failed to import: /opt/airflow/dags/Etl_weather.py
Traceback (most recent call last):
  File "/home/airflow/.local/lib/python3.12/site-packages/airflow/models/dagbag.py", line 383, in parse
    loader.exec_module(new_module)
  File "<frozen importlib._bootstrap_external>", line 995, in exec_module
  File "<frozen importlib._bootstrap>", line 488, in _call_with_frames_removed
  File "/opt/airflow/dags/Etl_weather.py", line 55, in <module>
    insert_data = PostgresFileOperator(
                  ^^^^^^^^^^^^^^^^^^^^^
TypeError: 'module' object is not callable
[2024-10-31T01:54:16.388+0000] {processor.py:927} WARNING - No viable dags retrieved from /opt/airflow/dags/Etl_weather.py
[2024-10-31T01:54:16.405+0000] {processor.py:208} INFO - Processing /opt/airflow/dags/Etl_weather.py took 0.054 seconds
[2024-10-31T01:54:46.713+0000] {processor.py:186} INFO - Started process (PID=58) to work on /opt/airflow/dags/Etl_weather.py
[2024-10-31T01:54:46.714+0000] {processor.py:914} INFO - Processing file /opt/airflow/dags/Etl_weather.py for tasks to queue
[2024-10-31T01:54:46.716+0000] {logging_mixin.py:190} INFO - [2024-10-31T01:54:46.715+0000] {dagbag.py:588} INFO - Filling up the DagBag from /opt/airflow/dags/Etl_weather.py
[2024-10-31T01:54:46.735+0000] {logging_mixin.py:190} INFO - [2024-10-31T01:54:46.733+0000] {dagbag.py:387} ERROR - Failed to import: /opt/airflow/dags/Etl_weather.py
Traceback (most recent call last):
  File "/home/airflow/.local/lib/python3.12/site-packages/airflow/models/dagbag.py", line 383, in parse
    loader.exec_module(new_module)
  File "<frozen importlib._bootstrap_external>", line 995, in exec_module
  File "<frozen importlib._bootstrap>", line 488, in _call_with_frames_removed
  File "/opt/airflow/dags/Etl_weather.py", line 55, in <module>
    insert_data = PostgresFileOperator(
                  ^^^^^^^^^^^^^^^^^^^^^
TypeError: 'module' object is not callable
[2024-10-31T01:54:46.736+0000] {processor.py:927} WARNING - No viable dags retrieved from /opt/airflow/dags/Etl_weather.py
[2024-10-31T01:54:46.752+0000] {processor.py:208} INFO - Processing /opt/airflow/dags/Etl_weather.py took 0.042 seconds
[2024-10-31T01:55:17.073+0000] {processor.py:186} INFO - Started process (PID=65) to work on /opt/airflow/dags/Etl_weather.py
[2024-10-31T01:55:17.074+0000] {processor.py:914} INFO - Processing file /opt/airflow/dags/Etl_weather.py for tasks to queue
[2024-10-31T01:55:17.076+0000] {logging_mixin.py:190} INFO - [2024-10-31T01:55:17.075+0000] {dagbag.py:588} INFO - Filling up the DagBag from /opt/airflow/dags/Etl_weather.py
[2024-10-31T01:55:17.097+0000] {logging_mixin.py:190} INFO - [2024-10-31T01:55:17.095+0000] {dagbag.py:387} ERROR - Failed to import: /opt/airflow/dags/Etl_weather.py
Traceback (most recent call last):
  File "/home/airflow/.local/lib/python3.12/site-packages/airflow/models/dagbag.py", line 383, in parse
    loader.exec_module(new_module)
  File "<frozen importlib._bootstrap_external>", line 995, in exec_module
  File "<frozen importlib._bootstrap>", line 488, in _call_with_frames_removed
  File "/opt/airflow/dags/Etl_weather.py", line 55, in <module>
    insert_data = PostgresFileOperator(
                  ^^^^^^^^^^^^^^^^^^^^^
TypeError: 'module' object is not callable
[2024-10-31T01:55:17.098+0000] {processor.py:927} WARNING - No viable dags retrieved from /opt/airflow/dags/Etl_weather.py
[2024-10-31T01:55:17.112+0000] {processor.py:208} INFO - Processing /opt/airflow/dags/Etl_weather.py took 0.043 seconds
[2024-10-31T01:55:47.349+0000] {processor.py:186} INFO - Started process (PID=72) to work on /opt/airflow/dags/Etl_weather.py
[2024-10-31T01:55:47.350+0000] {processor.py:914} INFO - Processing file /opt/airflow/dags/Etl_weather.py for tasks to queue
[2024-10-31T01:55:47.351+0000] {logging_mixin.py:190} INFO - [2024-10-31T01:55:47.351+0000] {dagbag.py:588} INFO - Filling up the DagBag from /opt/airflow/dags/Etl_weather.py
[2024-10-31T01:55:47.369+0000] {logging_mixin.py:190} INFO - [2024-10-31T01:55:47.367+0000] {dagbag.py:387} ERROR - Failed to import: /opt/airflow/dags/Etl_weather.py
Traceback (most recent call last):
  File "/home/airflow/.local/lib/python3.12/site-packages/airflow/models/dagbag.py", line 383, in parse
    loader.exec_module(new_module)
  File "<frozen importlib._bootstrap_external>", line 995, in exec_module
  File "<frozen importlib._bootstrap>", line 488, in _call_with_frames_removed
  File "/opt/airflow/dags/Etl_weather.py", line 55, in <module>
    insert_data = PostgresFileOperator(
                  ^^^^^^^^^^^^^^^^^^^^^
TypeError: 'module' object is not callable
[2024-10-31T01:55:47.370+0000] {processor.py:927} WARNING - No viable dags retrieved from /opt/airflow/dags/Etl_weather.py
[2024-10-31T01:55:47.384+0000] {processor.py:208} INFO - Processing /opt/airflow/dags/Etl_weather.py took 0.038 seconds
[2024-10-31T01:56:17.681+0000] {processor.py:186} INFO - Started process (PID=79) to work on /opt/airflow/dags/Etl_weather.py
[2024-10-31T01:56:17.682+0000] {processor.py:914} INFO - Processing file /opt/airflow/dags/Etl_weather.py for tasks to queue
[2024-10-31T01:56:17.684+0000] {logging_mixin.py:190} INFO - [2024-10-31T01:56:17.683+0000] {dagbag.py:588} INFO - Filling up the DagBag from /opt/airflow/dags/Etl_weather.py
[2024-10-31T01:56:17.711+0000] {logging_mixin.py:190} INFO - [2024-10-31T01:56:17.708+0000] {dagbag.py:387} ERROR - Failed to import: /opt/airflow/dags/Etl_weather.py
Traceback (most recent call last):
  File "/home/airflow/.local/lib/python3.12/site-packages/airflow/models/dagbag.py", line 383, in parse
    loader.exec_module(new_module)
  File "<frozen importlib._bootstrap_external>", line 995, in exec_module
  File "<frozen importlib._bootstrap>", line 488, in _call_with_frames_removed
  File "/opt/airflow/dags/Etl_weather.py", line 55, in <module>
    insert_data = PostgresFileOperator(
                  ^^^^^^^^^^^^^^^^^^^^^
TypeError: 'module' object is not callable
[2024-10-31T01:56:17.712+0000] {processor.py:927} WARNING - No viable dags retrieved from /opt/airflow/dags/Etl_weather.py
[2024-10-31T01:56:17.726+0000] {processor.py:208} INFO - Processing /opt/airflow/dags/Etl_weather.py took 0.049 seconds
[2024-10-31T01:56:48.066+0000] {processor.py:186} INFO - Started process (PID=86) to work on /opt/airflow/dags/Etl_weather.py
[2024-10-31T01:56:48.067+0000] {processor.py:914} INFO - Processing file /opt/airflow/dags/Etl_weather.py for tasks to queue
[2024-10-31T01:56:48.068+0000] {logging_mixin.py:190} INFO - [2024-10-31T01:56:48.068+0000] {dagbag.py:588} INFO - Filling up the DagBag from /opt/airflow/dags/Etl_weather.py
[2024-10-31T01:56:48.095+0000] {logging_mixin.py:190} INFO - [2024-10-31T01:56:48.092+0000] {dagbag.py:387} ERROR - Failed to import: /opt/airflow/dags/Etl_weather.py
Traceback (most recent call last):
  File "/home/airflow/.local/lib/python3.12/site-packages/airflow/models/dagbag.py", line 383, in parse
    loader.exec_module(new_module)
  File "<frozen importlib._bootstrap_external>", line 995, in exec_module
  File "<frozen importlib._bootstrap>", line 488, in _call_with_frames_removed
  File "/opt/airflow/dags/Etl_weather.py", line 55, in <module>
    insert_data = PostgresFileOperator(
                  ^^^^^^^^^^^^^^^^^^^^^
TypeError: 'module' object is not callable
[2024-10-31T01:56:48.096+0000] {processor.py:927} WARNING - No viable dags retrieved from /opt/airflow/dags/Etl_weather.py
[2024-10-31T01:56:48.110+0000] {processor.py:208} INFO - Processing /opt/airflow/dags/Etl_weather.py took 0.050 seconds
[2024-10-31T02:02:59.517+0000] {processor.py:186} INFO - Started process (PID=51) to work on /opt/airflow/dags/Etl_weather.py
[2024-10-31T02:02:59.518+0000] {processor.py:914} INFO - Processing file /opt/airflow/dags/Etl_weather.py for tasks to queue
[2024-10-31T02:02:59.520+0000] {logging_mixin.py:190} INFO - [2024-10-31T02:02:59.519+0000] {dagbag.py:588} INFO - Filling up the DagBag from /opt/airflow/dags/Etl_weather.py
[2024-10-31T02:02:59.549+0000] {logging_mixin.py:190} INFO - [2024-10-31T02:02:59.546+0000] {dagbag.py:387} ERROR - Failed to import: /opt/airflow/dags/Etl_weather.py
Traceback (most recent call last):
  File "/home/airflow/.local/lib/python3.12/site-packages/airflow/models/dagbag.py", line 383, in parse
    loader.exec_module(new_module)
  File "<frozen importlib._bootstrap_external>", line 995, in exec_module
  File "<frozen importlib._bootstrap>", line 488, in _call_with_frames_removed
  File "/opt/airflow/dags/Etl_weather.py", line 55, in <module>
    insert_data = PostgresFileOperator(
                  ^^^^^^^^^^^^^^^^^^^^^
TypeError: 'module' object is not callable
[2024-10-31T02:02:59.550+0000] {processor.py:927} WARNING - No viable dags retrieved from /opt/airflow/dags/Etl_weather.py
[2024-10-31T02:02:59.568+0000] {processor.py:208} INFO - Processing /opt/airflow/dags/Etl_weather.py took 0.056 seconds
[2024-10-31T02:03:29.811+0000] {processor.py:186} INFO - Started process (PID=58) to work on /opt/airflow/dags/Etl_weather.py
[2024-10-31T02:03:29.812+0000] {processor.py:914} INFO - Processing file /opt/airflow/dags/Etl_weather.py for tasks to queue
[2024-10-31T02:03:29.815+0000] {logging_mixin.py:190} INFO - [2024-10-31T02:03:29.814+0000] {dagbag.py:588} INFO - Filling up the DagBag from /opt/airflow/dags/Etl_weather.py
[2024-10-31T02:03:29.846+0000] {logging_mixin.py:190} INFO - [2024-10-31T02:03:29.843+0000] {dagbag.py:387} ERROR - Failed to import: /opt/airflow/dags/Etl_weather.py
Traceback (most recent call last):
  File "/home/airflow/.local/lib/python3.12/site-packages/airflow/models/dagbag.py", line 383, in parse
    loader.exec_module(new_module)
  File "<frozen importlib._bootstrap_external>", line 995, in exec_module
  File "<frozen importlib._bootstrap>", line 488, in _call_with_frames_removed
  File "/opt/airflow/dags/Etl_weather.py", line 55, in <module>
    insert_data = PostgresFileOperator(
                  ^^^^^^^^^^^^^^^^^^^^^
TypeError: 'module' object is not callable
[2024-10-31T02:03:29.847+0000] {processor.py:927} WARNING - No viable dags retrieved from /opt/airflow/dags/Etl_weather.py
[2024-10-31T02:03:29.866+0000] {processor.py:208} INFO - Processing /opt/airflow/dags/Etl_weather.py took 0.062 seconds
[2024-10-31T02:04:00.166+0000] {processor.py:186} INFO - Started process (PID=65) to work on /opt/airflow/dags/Etl_weather.py
[2024-10-31T02:04:00.167+0000] {processor.py:914} INFO - Processing file /opt/airflow/dags/Etl_weather.py for tasks to queue
[2024-10-31T02:04:00.169+0000] {logging_mixin.py:190} INFO - [2024-10-31T02:04:00.169+0000] {dagbag.py:588} INFO - Filling up the DagBag from /opt/airflow/dags/Etl_weather.py
[2024-10-31T02:04:00.195+0000] {logging_mixin.py:190} INFO - [2024-10-31T02:04:00.191+0000] {dagbag.py:387} ERROR - Failed to import: /opt/airflow/dags/Etl_weather.py
Traceback (most recent call last):
  File "/home/airflow/.local/lib/python3.12/site-packages/airflow/models/dagbag.py", line 383, in parse
    loader.exec_module(new_module)
  File "<frozen importlib._bootstrap_external>", line 995, in exec_module
  File "<frozen importlib._bootstrap>", line 488, in _call_with_frames_removed
  File "/opt/airflow/dags/Etl_weather.py", line 55, in <module>
    insert_data = PostgresFileOperator(
                  ^^^^^^^^^^^^^^^^^^^^^
TypeError: 'module' object is not callable
[2024-10-31T02:04:00.196+0000] {processor.py:927} WARNING - No viable dags retrieved from /opt/airflow/dags/Etl_weather.py
[2024-10-31T02:04:00.213+0000] {processor.py:208} INFO - Processing /opt/airflow/dags/Etl_weather.py took 0.050 seconds
[2024-10-31T02:04:30.539+0000] {processor.py:186} INFO - Started process (PID=72) to work on /opt/airflow/dags/Etl_weather.py
[2024-10-31T02:04:30.539+0000] {processor.py:914} INFO - Processing file /opt/airflow/dags/Etl_weather.py for tasks to queue
[2024-10-31T02:04:30.541+0000] {logging_mixin.py:190} INFO - [2024-10-31T02:04:30.541+0000] {dagbag.py:588} INFO - Filling up the DagBag from /opt/airflow/dags/Etl_weather.py
[2024-10-31T02:04:30.567+0000] {logging_mixin.py:190} INFO - [2024-10-31T02:04:30.563+0000] {dagbag.py:387} ERROR - Failed to import: /opt/airflow/dags/Etl_weather.py
Traceback (most recent call last):
  File "/home/airflow/.local/lib/python3.12/site-packages/airflow/models/dagbag.py", line 383, in parse
    loader.exec_module(new_module)
  File "<frozen importlib._bootstrap_external>", line 995, in exec_module
  File "<frozen importlib._bootstrap>", line 488, in _call_with_frames_removed
  File "/opt/airflow/dags/Etl_weather.py", line 55, in <module>
    insert_data = PostgresFileOperator(
                  ^^^^^^^^^^^^^^^^^^^^^
TypeError: 'module' object is not callable
[2024-10-31T02:04:30.568+0000] {processor.py:927} WARNING - No viable dags retrieved from /opt/airflow/dags/Etl_weather.py
[2024-10-31T02:04:30.583+0000] {processor.py:208} INFO - Processing /opt/airflow/dags/Etl_weather.py took 0.049 seconds
[2024-10-31T02:05:00.865+0000] {processor.py:186} INFO - Started process (PID=79) to work on /opt/airflow/dags/Etl_weather.py
[2024-10-31T02:05:00.866+0000] {processor.py:914} INFO - Processing file /opt/airflow/dags/Etl_weather.py for tasks to queue
[2024-10-31T02:05:00.868+0000] {logging_mixin.py:190} INFO - [2024-10-31T02:05:00.868+0000] {dagbag.py:588} INFO - Filling up the DagBag from /opt/airflow/dags/Etl_weather.py
[2024-10-31T02:05:00.891+0000] {logging_mixin.py:190} INFO - [2024-10-31T02:05:00.889+0000] {dagbag.py:387} ERROR - Failed to import: /opt/airflow/dags/Etl_weather.py
Traceback (most recent call last):
  File "/home/airflow/.local/lib/python3.12/site-packages/airflow/models/dagbag.py", line 383, in parse
    loader.exec_module(new_module)
  File "<frozen importlib._bootstrap_external>", line 995, in exec_module
  File "<frozen importlib._bootstrap>", line 488, in _call_with_frames_removed
  File "/opt/airflow/dags/Etl_weather.py", line 55, in <module>
    insert_data = PostgresFileOperator(
                  ^^^^^^^^^^^^^^^^^^^^^
TypeError: 'module' object is not callable
[2024-10-31T02:05:00.892+0000] {processor.py:927} WARNING - No viable dags retrieved from /opt/airflow/dags/Etl_weather.py
[2024-10-31T02:05:00.904+0000] {processor.py:208} INFO - Processing /opt/airflow/dags/Etl_weather.py took 0.045 seconds
[2024-10-31T02:05:31.204+0000] {processor.py:186} INFO - Started process (PID=86) to work on /opt/airflow/dags/Etl_weather.py
[2024-10-31T02:05:31.204+0000] {processor.py:914} INFO - Processing file /opt/airflow/dags/Etl_weather.py for tasks to queue
[2024-10-31T02:05:31.206+0000] {logging_mixin.py:190} INFO - [2024-10-31T02:05:31.206+0000] {dagbag.py:588} INFO - Filling up the DagBag from /opt/airflow/dags/Etl_weather.py
[2024-10-31T02:05:31.233+0000] {logging_mixin.py:190} INFO - [2024-10-31T02:05:31.230+0000] {dagbag.py:387} ERROR - Failed to import: /opt/airflow/dags/Etl_weather.py
Traceback (most recent call last):
  File "/home/airflow/.local/lib/python3.12/site-packages/airflow/models/dagbag.py", line 383, in parse
    loader.exec_module(new_module)
  File "<frozen importlib._bootstrap_external>", line 995, in exec_module
  File "<frozen importlib._bootstrap>", line 488, in _call_with_frames_removed
  File "/opt/airflow/dags/Etl_weather.py", line 55, in <module>
    insert_data = PostgresFileOperator(
                  ^^^^^^^^^^^^^^^^^^^^^
TypeError: 'module' object is not callable
[2024-10-31T02:05:31.234+0000] {processor.py:927} WARNING - No viable dags retrieved from /opt/airflow/dags/Etl_weather.py
[2024-10-31T02:05:31.249+0000] {processor.py:208} INFO - Processing /opt/airflow/dags/Etl_weather.py took 0.049 seconds
[2024-10-31T02:06:01.529+0000] {processor.py:186} INFO - Started process (PID=99) to work on /opt/airflow/dags/Etl_weather.py
[2024-10-31T02:06:01.530+0000] {processor.py:914} INFO - Processing file /opt/airflow/dags/Etl_weather.py for tasks to queue
[2024-10-31T02:06:01.532+0000] {logging_mixin.py:190} INFO - [2024-10-31T02:06:01.532+0000] {dagbag.py:588} INFO - Filling up the DagBag from /opt/airflow/dags/Etl_weather.py
[2024-10-31T02:06:01.558+0000] {logging_mixin.py:190} INFO - [2024-10-31T02:06:01.551+0000] {dagbag.py:387} ERROR - Failed to import: /opt/airflow/dags/Etl_weather.py
Traceback (most recent call last):
  File "/home/airflow/.local/lib/python3.12/site-packages/airflow/models/dagbag.py", line 383, in parse
    loader.exec_module(new_module)
  File "<frozen importlib._bootstrap_external>", line 995, in exec_module
  File "<frozen importlib._bootstrap>", line 488, in _call_with_frames_removed
  File "/opt/airflow/dags/Etl_weather.py", line 55, in <module>
    insert_data = PostgresFileOperator(
                  ^^^^^^^^^^^^^^^^^^^^^
TypeError: 'module' object is not callable
[2024-10-31T02:06:01.560+0000] {processor.py:927} WARNING - No viable dags retrieved from /opt/airflow/dags/Etl_weather.py
[2024-10-31T02:06:01.577+0000] {processor.py:208} INFO - Processing /opt/airflow/dags/Etl_weather.py took 0.052 seconds
[2024-10-31T02:06:31.837+0000] {processor.py:186} INFO - Started process (PID=106) to work on /opt/airflow/dags/Etl_weather.py
[2024-10-31T02:06:31.838+0000] {processor.py:914} INFO - Processing file /opt/airflow/dags/Etl_weather.py for tasks to queue
[2024-10-31T02:06:31.839+0000] {logging_mixin.py:190} INFO - [2024-10-31T02:06:31.839+0000] {dagbag.py:588} INFO - Filling up the DagBag from /opt/airflow/dags/Etl_weather.py
[2024-10-31T02:06:31.864+0000] {logging_mixin.py:190} INFO - [2024-10-31T02:06:31.861+0000] {dagbag.py:387} ERROR - Failed to import: /opt/airflow/dags/Etl_weather.py
Traceback (most recent call last):
  File "/home/airflow/.local/lib/python3.12/site-packages/airflow/models/dagbag.py", line 383, in parse
    loader.exec_module(new_module)
  File "<frozen importlib._bootstrap_external>", line 995, in exec_module
  File "<frozen importlib._bootstrap>", line 488, in _call_with_frames_removed
  File "/opt/airflow/dags/Etl_weather.py", line 55, in <module>
    insert_data = PostgresFileOperator(
                  ^^^^^^^^^^^^^^^^^^^^^
TypeError: 'module' object is not callable
[2024-10-31T02:06:31.865+0000] {processor.py:927} WARNING - No viable dags retrieved from /opt/airflow/dags/Etl_weather.py
[2024-10-31T02:06:31.879+0000] {processor.py:208} INFO - Processing /opt/airflow/dags/Etl_weather.py took 0.045 seconds
[2024-10-31T02:06:47.007+0000] {processor.py:186} INFO - Started process (PID=107) to work on /opt/airflow/dags/Etl_weather.py
[2024-10-31T02:06:47.008+0000] {processor.py:914} INFO - Processing file /opt/airflow/dags/Etl_weather.py for tasks to queue
[2024-10-31T02:06:47.010+0000] {logging_mixin.py:190} INFO - [2024-10-31T02:06:47.010+0000] {dagbag.py:588} INFO - Filling up the DagBag from /opt/airflow/dags/Etl_weather.py
[2024-10-31T02:06:47.037+0000] {logging_mixin.py:190} INFO - [2024-10-31T02:06:47.033+0000] {dagbag.py:387} ERROR - Failed to import: /opt/airflow/dags/Etl_weather.py
Traceback (most recent call last):
  File "/home/airflow/.local/lib/python3.12/site-packages/airflow/models/dagbag.py", line 383, in parse
    loader.exec_module(new_module)
  File "<frozen importlib._bootstrap_external>", line 995, in exec_module
  File "<frozen importlib._bootstrap>", line 488, in _call_with_frames_removed
  File "/opt/airflow/dags/Etl_weather.py", line 8, in <module>
    from airflow.operators import PostgresFileOperator
ImportError: cannot import name 'PostgresFileOperator' from 'airflow.operators' (/home/airflow/.local/lib/python3.12/site-packages/airflow/operators/__init__.py)
[2024-10-31T02:06:47.039+0000] {processor.py:927} WARNING - No viable dags retrieved from /opt/airflow/dags/Etl_weather.py
[2024-10-31T02:06:47.053+0000] {processor.py:208} INFO - Processing /opt/airflow/dags/Etl_weather.py took 0.050 seconds
[2024-10-31T02:06:56.142+0000] {processor.py:186} INFO - Started process (PID=108) to work on /opt/airflow/dags/Etl_weather.py
[2024-10-31T02:06:56.142+0000] {processor.py:914} INFO - Processing file /opt/airflow/dags/Etl_weather.py for tasks to queue
[2024-10-31T02:06:56.144+0000] {logging_mixin.py:190} INFO - [2024-10-31T02:06:56.144+0000] {dagbag.py:588} INFO - Filling up the DagBag from /opt/airflow/dags/Etl_weather.py
[2024-10-31T02:06:56.161+0000] {logging_mixin.py:190} INFO - [2024-10-31T02:06:56.158+0000] {dagbag.py:387} ERROR - Failed to import: /opt/airflow/dags/Etl_weather.py
Traceback (most recent call last):
  File "/home/airflow/.local/lib/python3.12/site-packages/airflow/models/dagbag.py", line 383, in parse
    loader.exec_module(new_module)
  File "<frozen importlib._bootstrap_external>", line 995, in exec_module
  File "<frozen importlib._bootstrap>", line 488, in _call_with_frames_removed
  File "/opt/airflow/dags/Etl_weather.py", line 8, in <module>
    from airflow.operators.Postgres import PostgresFileOperator
ModuleNotFoundError: No module named 'airflow.operators.Postgres'
[2024-10-31T02:06:56.162+0000] {processor.py:927} WARNING - No viable dags retrieved from /opt/airflow/dags/Etl_weather.py
[2024-10-31T02:06:56.177+0000] {processor.py:208} INFO - Processing /opt/airflow/dags/Etl_weather.py took 0.039 seconds
[2024-10-31T02:07:01.210+0000] {processor.py:186} INFO - Started process (PID=109) to work on /opt/airflow/dags/Etl_weather.py
[2024-10-31T02:07:01.211+0000] {processor.py:914} INFO - Processing file /opt/airflow/dags/Etl_weather.py for tasks to queue
[2024-10-31T02:07:01.212+0000] {logging_mixin.py:190} INFO - [2024-10-31T02:07:01.212+0000] {dagbag.py:588} INFO - Filling up the DagBag from /opt/airflow/dags/Etl_weather.py
[2024-10-31T02:07:01.223+0000] {logging_mixin.py:190} INFO - [2024-10-31T02:07:01.222+0000] {dagbag.py:387} ERROR - Failed to import: /opt/airflow/dags/Etl_weather.py
Traceback (most recent call last):
  File "/home/airflow/.local/lib/python3.12/site-packages/airflow/models/dagbag.py", line 383, in parse
    loader.exec_module(new_module)
  File "<frozen importlib._bootstrap_external>", line 991, in exec_module
  File "<frozen importlib._bootstrap_external>", line 1129, in get_code
  File "<frozen importlib._bootstrap_external>", line 1059, in source_to_code
  File "<frozen importlib._bootstrap>", line 488, in _call_with_frames_removed
  File "/opt/airflow/dags/Etl_weather.py", line 8
    from  import PostgresFileOperator
          ^^^^^^
SyntaxError: invalid syntax
[2024-10-31T02:07:01.223+0000] {processor.py:927} WARNING - No viable dags retrieved from /opt/airflow/dags/Etl_weather.py
[2024-10-31T02:07:01.236+0000] {processor.py:208} INFO - Processing /opt/airflow/dags/Etl_weather.py took 0.030 seconds
[2024-10-31T02:07:06.302+0000] {processor.py:186} INFO - Started process (PID=116) to work on /opt/airflow/dags/Etl_weather.py
[2024-10-31T02:07:06.302+0000] {processor.py:914} INFO - Processing file /opt/airflow/dags/Etl_weather.py for tasks to queue
[2024-10-31T02:07:06.304+0000] {logging_mixin.py:190} INFO - [2024-10-31T02:07:06.304+0000] {dagbag.py:588} INFO - Filling up the DagBag from /opt/airflow/dags/Etl_weather.py
[2024-10-31T02:07:06.324+0000] {logging_mixin.py:190} INFO - [2024-10-31T02:07:06.321+0000] {dagbag.py:387} ERROR - Failed to import: /opt/airflow/dags/Etl_weather.py
Traceback (most recent call last):
  File "/home/airflow/.local/lib/python3.12/site-packages/airflow/models/dagbag.py", line 383, in parse
    loader.exec_module(new_module)
  File "<frozen importlib._bootstrap_external>", line 995, in exec_module
  File "<frozen importlib._bootstrap>", line 488, in _call_with_frames_removed
  File "/opt/airflow/dags/Etl_weather.py", line 8, in <module>
    from plugins.operators import PostgresFileOperator
ModuleNotFoundError: No module named 'plugins'
[2024-10-31T02:07:06.325+0000] {processor.py:927} WARNING - No viable dags retrieved from /opt/airflow/dags/Etl_weather.py
[2024-10-31T02:07:06.343+0000] {processor.py:208} INFO - Processing /opt/airflow/dags/Etl_weather.py took 0.045 seconds
[2024-10-31T02:07:21.481+0000] {processor.py:186} INFO - Started process (PID=117) to work on /opt/airflow/dags/Etl_weather.py
[2024-10-31T02:07:21.482+0000] {processor.py:914} INFO - Processing file /opt/airflow/dags/Etl_weather.py for tasks to queue
[2024-10-31T02:07:21.483+0000] {logging_mixin.py:190} INFO - [2024-10-31T02:07:21.483+0000] {dagbag.py:588} INFO - Filling up the DagBag from /opt/airflow/dags/Etl_weather.py
[2024-10-31T02:07:21.516+0000] {logging_mixin.py:190} INFO - [2024-10-31T02:07:21.514+0000] {dagbag.py:387} ERROR - Failed to import: /opt/airflow/dags/Etl_weather.py
Traceback (most recent call last):
  File "/home/airflow/.local/lib/python3.12/site-packages/airflow/models/dagbag.py", line 383, in parse
    loader.exec_module(new_module)
  File "<frozen importlib._bootstrap_external>", line 995, in exec_module
  File "<frozen importlib._bootstrap>", line 488, in _call_with_frames_removed
  File "/opt/airflow/dags/Etl_weather.py", line 55, in <module>
    insert_data = PostgresFileOperator(
                  ^^^^^^^^^^^^^^^^^^^^^
TypeError: 'module' object is not callable
[2024-10-31T02:07:21.517+0000] {processor.py:927} WARNING - No viable dags retrieved from /opt/airflow/dags/Etl_weather.py
[2024-10-31T02:07:21.531+0000] {processor.py:208} INFO - Processing /opt/airflow/dags/Etl_weather.py took 0.055 seconds
[2024-10-31T02:07:39.708+0000] {processor.py:186} INFO - Started process (PID=124) to work on /opt/airflow/dags/Etl_weather.py
[2024-10-31T02:07:39.709+0000] {processor.py:914} INFO - Processing file /opt/airflow/dags/Etl_weather.py for tasks to queue
[2024-10-31T02:07:39.711+0000] {logging_mixin.py:190} INFO - [2024-10-31T02:07:39.711+0000] {dagbag.py:588} INFO - Filling up the DagBag from /opt/airflow/dags/Etl_weather.py
[2024-10-31T02:07:39.733+0000] {logging_mixin.py:190} INFO - [2024-10-31T02:07:39.729+0000] {dagbag.py:387} ERROR - Failed to import: /opt/airflow/dags/Etl_weather.py
Traceback (most recent call last):
  File "/home/airflow/.local/lib/python3.12/site-packages/airflow/models/dagbag.py", line 383, in parse
    loader.exec_module(new_module)
  File "<frozen importlib._bootstrap_external>", line 995, in exec_module
  File "<frozen importlib._bootstrap>", line 488, in _call_with_frames_removed
  File "/opt/airflow/dags/Etl_weather.py", line 8, in <module>
    from plugins.operators import PostgresFileOperator
ModuleNotFoundError: No module named 'plugins'
[2024-10-31T02:07:39.734+0000] {processor.py:927} WARNING - No viable dags retrieved from /opt/airflow/dags/Etl_weather.py
[2024-10-31T02:07:39.746+0000] {processor.py:208} INFO - Processing /opt/airflow/dags/Etl_weather.py took 0.041 seconds
[2024-10-31T02:07:41.752+0000] {processor.py:186} INFO - Started process (PID=125) to work on /opt/airflow/dags/Etl_weather.py
[2024-10-31T02:07:41.753+0000] {processor.py:914} INFO - Processing file /opt/airflow/dags/Etl_weather.py for tasks to queue
[2024-10-31T02:07:41.755+0000] {logging_mixin.py:190} INFO - [2024-10-31T02:07:41.755+0000] {dagbag.py:588} INFO - Filling up the DagBag from /opt/airflow/dags/Etl_weather.py
[2024-10-31T02:07:41.780+0000] {logging_mixin.py:190} INFO - [2024-10-31T02:07:41.777+0000] {dagbag.py:387} ERROR - Failed to import: /opt/airflow/dags/Etl_weather.py
Traceback (most recent call last):
  File "/home/airflow/.local/lib/python3.12/site-packages/airflow/models/dagbag.py", line 383, in parse
    loader.exec_module(new_module)
  File "<frozen importlib._bootstrap_external>", line 995, in exec_module
  File "<frozen importlib._bootstrap>", line 488, in _call_with_frames_removed
  File "/opt/airflow/dags/Etl_weather.py", line 8, in <module>
    from plugins.operatorsoperators import PostgresFileOperator
ModuleNotFoundError: No module named 'plugins'
[2024-10-31T02:07:41.781+0000] {processor.py:927} WARNING - No viable dags retrieved from /opt/airflow/dags/Etl_weather.py
[2024-10-31T02:07:41.798+0000] {processor.py:208} INFO - Processing /opt/airflow/dags/Etl_weather.py took 0.050 seconds
[2024-10-31T02:07:45.834+0000] {processor.py:186} INFO - Started process (PID=126) to work on /opt/airflow/dags/Etl_weather.py
[2024-10-31T02:07:45.835+0000] {processor.py:914} INFO - Processing file /opt/airflow/dags/Etl_weather.py for tasks to queue
[2024-10-31T02:07:45.837+0000] {logging_mixin.py:190} INFO - [2024-10-31T02:07:45.837+0000] {dagbag.py:588} INFO - Filling up the DagBag from /opt/airflow/dags/Etl_weather.py
[2024-10-31T02:07:45.860+0000] {logging_mixin.py:190} INFO - [2024-10-31T02:07:45.857+0000] {dagbag.py:387} ERROR - Failed to import: /opt/airflow/dags/Etl_weather.py
Traceback (most recent call last):
  File "/home/airflow/.local/lib/python3.12/site-packages/airflow/models/dagbag.py", line 383, in parse
    loader.exec_module(new_module)
  File "<frozen importlib._bootstrap_external>", line 995, in exec_module
  File "<frozen importlib._bootstrap>", line 488, in _call_with_frames_removed
  File "/opt/airflow/dags/Etl_weather.py", line 8, in <module>
    from plugins.operators import PostgresFileOperator
ModuleNotFoundError: No module named 'plugins'
[2024-10-31T02:07:45.861+0000] {processor.py:927} WARNING - No viable dags retrieved from /opt/airflow/dags/Etl_weather.py
[2024-10-31T02:07:45.875+0000] {processor.py:208} INFO - Processing /opt/airflow/dags/Etl_weather.py took 0.044 seconds
[2024-10-31T02:08:14.164+0000] {processor.py:186} INFO - Started process (PID=133) to work on /opt/airflow/dags/Etl_weather.py
[2024-10-31T02:08:14.165+0000] {processor.py:914} INFO - Processing file /opt/airflow/dags/Etl_weather.py for tasks to queue
[2024-10-31T02:08:14.167+0000] {logging_mixin.py:190} INFO - [2024-10-31T02:08:14.167+0000] {dagbag.py:588} INFO - Filling up the DagBag from /opt/airflow/dags/Etl_weather.py
[2024-10-31T02:08:14.202+0000] {logging_mixin.py:190} INFO - [2024-10-31T02:08:14.199+0000] {dagbag.py:387} ERROR - Failed to import: /opt/airflow/dags/Etl_weather.py
Traceback (most recent call last):
  File "/home/airflow/.local/lib/python3.12/site-packages/airflow/models/dagbag.py", line 383, in parse
    loader.exec_module(new_module)
  File "<frozen importlib._bootstrap_external>", line 995, in exec_module
  File "<frozen importlib._bootstrap>", line 488, in _call_with_frames_removed
  File "/opt/airflow/dags/Etl_weather.py", line 55, in <module>
    insert_data = PostgresFileOperator(
                  ^^^^^^^^^^^^^^^^^^^^^
TypeError: 'module' object is not callable
[2024-10-31T02:08:14.204+0000] {processor.py:927} WARNING - No viable dags retrieved from /opt/airflow/dags/Etl_weather.py
[2024-10-31T02:08:14.221+0000] {processor.py:208} INFO - Processing /opt/airflow/dags/Etl_weather.py took 0.060 seconds
[2024-10-31T02:08:27.369+0000] {processor.py:186} INFO - Started process (PID=134) to work on /opt/airflow/dags/Etl_weather.py
[2024-10-31T02:08:27.370+0000] {processor.py:914} INFO - Processing file /opt/airflow/dags/Etl_weather.py for tasks to queue
[2024-10-31T02:08:27.371+0000] {logging_mixin.py:190} INFO - [2024-10-31T02:08:27.371+0000] {dagbag.py:588} INFO - Filling up the DagBag from /opt/airflow/dags/Etl_weather.py
[2024-10-31T02:08:27.417+0000] {processor.py:925} INFO - DAG(s) 'weather_dag' retrieved from /opt/airflow/dags/Etl_weather.py
[2024-10-31T02:08:27.577+0000] {logging_mixin.py:190} INFO - [2024-10-31T02:08:27.577+0000] {dag.py:3239} INFO - Sync 1 DAGs
[2024-10-31T02:08:27.593+0000] {logging_mixin.py:190} INFO - [2024-10-31T02:08:27.592+0000] {dag.py:4180} INFO - Setting next_dagrun for weather_dag to 2024-10-31 00:00:00+00:00, run_after=2024-11-01 00:00:00+00:00
[2024-10-31T02:08:27.609+0000] {processor.py:208} INFO - Processing /opt/airflow/dags/Etl_weather.py took 0.245 seconds
[2024-10-31T02:08:34.472+0000] {processor.py:186} INFO - Started process (PID=141) to work on /opt/airflow/dags/Etl_weather.py
[2024-10-31T02:08:34.473+0000] {processor.py:914} INFO - Processing file /opt/airflow/dags/Etl_weather.py for tasks to queue
[2024-10-31T02:08:34.475+0000] {logging_mixin.py:190} INFO - [2024-10-31T02:08:34.475+0000] {dagbag.py:588} INFO - Filling up the DagBag from /opt/airflow/dags/Etl_weather.py
[2024-10-31T02:08:34.499+0000] {processor.py:925} INFO - DAG(s) 'weather_dag' retrieved from /opt/airflow/dags/Etl_weather.py
[2024-10-31T02:08:34.509+0000] {logging_mixin.py:190} INFO - [2024-10-31T02:08:34.509+0000] {dag.py:3239} INFO - Sync 1 DAGs
[2024-10-31T02:08:34.536+0000] {logging_mixin.py:190} INFO - [2024-10-31T02:08:34.536+0000] {dag.py:4180} INFO - Setting next_dagrun for weather_dag to 2024-10-31 00:00:00+00:00, run_after=2024-11-01 00:00:00+00:00
[2024-10-31T02:08:34.559+0000] {processor.py:208} INFO - Processing /opt/airflow/dags/Etl_weather.py took 0.090 seconds
[2024-10-31T02:09:04.803+0000] {processor.py:186} INFO - Started process (PID=148) to work on /opt/airflow/dags/Etl_weather.py
[2024-10-31T02:09:04.804+0000] {processor.py:914} INFO - Processing file /opt/airflow/dags/Etl_weather.py for tasks to queue
[2024-10-31T02:09:04.806+0000] {logging_mixin.py:190} INFO - [2024-10-31T02:09:04.806+0000] {dagbag.py:588} INFO - Filling up the DagBag from /opt/airflow/dags/Etl_weather.py
[2024-10-31T02:09:04.829+0000] {processor.py:925} INFO - DAG(s) 'weather_dag' retrieved from /opt/airflow/dags/Etl_weather.py
[2024-10-31T02:09:04.852+0000] {logging_mixin.py:190} INFO - [2024-10-31T02:09:04.852+0000] {dag.py:3239} INFO - Sync 1 DAGs
[2024-10-31T02:09:04.874+0000] {logging_mixin.py:190} INFO - [2024-10-31T02:09:04.874+0000] {dag.py:4180} INFO - Setting next_dagrun for weather_dag to 2024-10-31 00:00:00+00:00, run_after=2024-11-01 00:00:00+00:00
[2024-10-31T02:09:04.889+0000] {processor.py:208} INFO - Processing /opt/airflow/dags/Etl_weather.py took 0.091 seconds
[2024-10-31T02:09:35.149+0000] {processor.py:186} INFO - Started process (PID=155) to work on /opt/airflow/dags/Etl_weather.py
[2024-10-31T02:09:35.150+0000] {processor.py:914} INFO - Processing file /opt/airflow/dags/Etl_weather.py for tasks to queue
[2024-10-31T02:09:35.153+0000] {logging_mixin.py:190} INFO - [2024-10-31T02:09:35.153+0000] {dagbag.py:588} INFO - Filling up the DagBag from /opt/airflow/dags/Etl_weather.py
[2024-10-31T02:09:35.170+0000] {processor.py:925} INFO - DAG(s) 'weather_dag' retrieved from /opt/airflow/dags/Etl_weather.py
[2024-10-31T02:09:35.192+0000] {logging_mixin.py:190} INFO - [2024-10-31T02:09:35.192+0000] {dag.py:3239} INFO - Sync 1 DAGs
[2024-10-31T02:09:35.213+0000] {logging_mixin.py:190} INFO - [2024-10-31T02:09:35.213+0000] {dag.py:4180} INFO - Setting next_dagrun for weather_dag to 2024-10-31 00:00:00+00:00, run_after=2024-11-01 00:00:00+00:00
[2024-10-31T02:09:35.230+0000] {processor.py:208} INFO - Processing /opt/airflow/dags/Etl_weather.py took 0.085 seconds
[2024-10-31T02:10:05.498+0000] {processor.py:186} INFO - Started process (PID=162) to work on /opt/airflow/dags/Etl_weather.py
[2024-10-31T02:10:05.499+0000] {processor.py:914} INFO - Processing file /opt/airflow/dags/Etl_weather.py for tasks to queue
[2024-10-31T02:10:05.501+0000] {logging_mixin.py:190} INFO - [2024-10-31T02:10:05.501+0000] {dagbag.py:588} INFO - Filling up the DagBag from /opt/airflow/dags/Etl_weather.py
[2024-10-31T02:10:05.528+0000] {processor.py:925} INFO - DAG(s) 'weather_dag' retrieved from /opt/airflow/dags/Etl_weather.py
[2024-10-31T02:10:05.557+0000] {logging_mixin.py:190} INFO - [2024-10-31T02:10:05.556+0000] {dag.py:3239} INFO - Sync 1 DAGs
[2024-10-31T02:10:05.580+0000] {logging_mixin.py:190} INFO - [2024-10-31T02:10:05.580+0000] {dag.py:4180} INFO - Setting next_dagrun for weather_dag to 2024-10-31 00:00:00+00:00, run_after=2024-11-01 00:00:00+00:00
[2024-10-31T02:10:05.600+0000] {processor.py:208} INFO - Processing /opt/airflow/dags/Etl_weather.py took 0.106 seconds
