[2024-10-24T00:56:41.487+0000] {local_task_job_runner.py:123} INFO - ::group::Pre task execution logs
[2024-10-24T00:56:41.509+0000] {taskinstance.py:2612} INFO - Dependencies all met for dep_context=non-requeueable deps ti=<TaskInstance: weather_dag.extract_data manual__2024-10-24T00:56:38.666195+00:00 [queued]>
[2024-10-24T00:56:41.520+0000] {taskinstance.py:2612} INFO - Dependencies all met for dep_context=requeueable deps ti=<TaskInstance: weather_dag.extract_data manual__2024-10-24T00:56:38.666195+00:00 [queued]>
[2024-10-24T00:56:41.521+0000] {taskinstance.py:2865} INFO - Starting attempt 1 of 2
[2024-10-24T00:56:41.533+0000] {taskinstance.py:2888} INFO - Executing <Task(BashOperator): extract_data> on 2024-10-24 00:56:38.666195+00:00
[2024-10-24T00:56:41.538+0000] {warnings.py:112} WARNING - /home/***/.local/lib/python3.12/site-packages/***/task/task_runner/standard_task_runner.py:70: DeprecationWarning: This process (pid=75) is multi-threaded, use of fork() may lead to deadlocks in the child.
  pid = os.fork()

[2024-10-24T00:56:41.539+0000] {standard_task_runner.py:72} INFO - Started process 76 to run task
[2024-10-24T00:56:41.539+0000] {standard_task_runner.py:104} INFO - Running: ['***', 'tasks', 'run', 'weather_dag', 'extract_data', 'manual__2024-10-24T00:56:38.666195+00:00', '--job-id', '8', '--raw', '--subdir', 'DAGS_FOLDER/Etl_weather.py', '--cfg-path', '/tmp/tmp0s3th_3x']
[2024-10-24T00:56:41.541+0000] {standard_task_runner.py:105} INFO - Job 8: Subtask extract_data
[2024-10-24T00:56:41.588+0000] {task_command.py:467} INFO - Running <TaskInstance: weather_dag.extract_data manual__2024-10-24T00:56:38.666195+00:00 [running]> on host 9ec308eea9c2
[2024-10-24T00:56:41.655+0000] {taskinstance.py:3131} INFO - Exporting env vars: AIRFLOW_CTX_DAG_EMAIL='milo0@gmail.com' AIRFLOW_CTX_DAG_OWNER='milo' AIRFLOW_CTX_DAG_ID='weather_dag' AIRFLOW_CTX_TASK_ID='extract_data' AIRFLOW_CTX_EXECUTION_DATE='2024-10-24T00:56:38.666195+00:00' AIRFLOW_CTX_TRY_NUMBER='1' AIRFLOW_CTX_DAG_RUN_ID='manual__2024-10-24T00:56:38.666195+00:00'
[2024-10-24T00:56:41.656+0000] {taskinstance.py:731} INFO - ::endgroup::
[2024-10-24T00:56:41.669+0000] {subprocess.py:63} INFO - Tmp dir root location: /tmp
[2024-10-24T00:56:41.671+0000] {subprocess.py:75} INFO - Running command: ['/usr/bin/bash', '-c', 'python /opt/***/tmp/extract_data_api']
[2024-10-24T00:56:41.678+0000] {subprocess.py:86} INFO - Output:
[2024-10-24T00:56:41.705+0000] {subprocess.py:93} INFO - python: can't open file '/opt/***/tmp/extract_data_api': [Errno 2] No such file or directory
[2024-10-24T00:56:41.708+0000] {subprocess.py:97} INFO - Command exited with return code 2
[2024-10-24T00:56:41.717+0000] {taskinstance.py:3310} ERROR - Task failed with exception
Traceback (most recent call last):
  File "/home/airflow/.local/lib/python3.12/site-packages/airflow/models/taskinstance.py", line 767, in _execute_task
    result = _execute_callable(context=context, **execute_callable_kwargs)
             ^^^^^^^^^^^^^^^^^^^^^^^^^^^^^^^^^^^^^^^^^^^^^^^^^^^^^^^^^^^^^
  File "/home/airflow/.local/lib/python3.12/site-packages/airflow/models/taskinstance.py", line 733, in _execute_callable
    return ExecutionCallableRunner(
           ^^^^^^^^^^^^^^^^^^^^^^^^
  File "/home/airflow/.local/lib/python3.12/site-packages/airflow/utils/operator_helpers.py", line 252, in run
    return self.func(*args, **kwargs)
           ^^^^^^^^^^^^^^^^^^^^^^^^^^
  File "/home/airflow/.local/lib/python3.12/site-packages/airflow/models/baseoperator.py", line 406, in wrapper
    return func(self, *args, **kwargs)
           ^^^^^^^^^^^^^^^^^^^^^^^^^^^
  File "/home/airflow/.local/lib/python3.12/site-packages/airflow/operators/bash.py", line 249, in execute
    raise AirflowException(
airflow.exceptions.AirflowException: Bash command failed. The command returned a non-zero exit code 2.
[2024-10-24T00:56:41.725+0000] {taskinstance.py:1225} INFO - Marking task as UP_FOR_RETRY. dag_id=weather_dag, task_id=extract_data, run_id=manual__2024-10-24T00:56:38.666195+00:00, execution_date=20241024T005638, start_date=20241024T005641, end_date=20241024T005641
[2024-10-24T00:56:41.740+0000] {taskinstance.py:340} INFO - ::group::Post task execution logs
[2024-10-24T00:56:41.741+0000] {standard_task_runner.py:124} ERROR - Failed to execute job 8 for task extract_data (Bash command failed. The command returned a non-zero exit code 2.; 76)
Traceback (most recent call last):
  File "/home/airflow/.local/lib/python3.12/site-packages/airflow/task/task_runner/standard_task_runner.py", line 117, in _start_by_fork
    ret = args.func(args, dag=self.dag)
          ^^^^^^^^^^^^^^^^^^^^^^^^^^^^^
  File "/home/airflow/.local/lib/python3.12/site-packages/airflow/cli/cli_config.py", line 49, in command
    return func(*args, **kwargs)
           ^^^^^^^^^^^^^^^^^^^^^
  File "/home/airflow/.local/lib/python3.12/site-packages/airflow/utils/cli.py", line 115, in wrapper
    return f(*args, **kwargs)
           ^^^^^^^^^^^^^^^^^^
  File "/home/airflow/.local/lib/python3.12/site-packages/airflow/cli/commands/task_command.py", line 483, in task_run
    task_return_code = _run_task_by_selected_method(args, _dag, ti)
                       ^^^^^^^^^^^^^^^^^^^^^^^^^^^^^^^^^^^^^^^^^^^^
  File "/home/airflow/.local/lib/python3.12/site-packages/airflow/cli/commands/task_command.py", line 256, in _run_task_by_selected_method
    return _run_raw_task(args, ti)
           ^^^^^^^^^^^^^^^^^^^^^^^
  File "/home/airflow/.local/lib/python3.12/site-packages/airflow/cli/commands/task_command.py", line 341, in _run_raw_task
    return ti._run_raw_task(
           ^^^^^^^^^^^^^^^^^
  File "/home/airflow/.local/lib/python3.12/site-packages/airflow/utils/session.py", line 97, in wrapper
    return func(*args, session=session, **kwargs)
           ^^^^^^^^^^^^^^^^^^^^^^^^^^^^^^^^^^^^^^
  File "/home/airflow/.local/lib/python3.12/site-packages/airflow/models/taskinstance.py", line 3004, in _run_raw_task
    return _run_raw_task(
           ^^^^^^^^^^^^^^
  File "/home/airflow/.local/lib/python3.12/site-packages/airflow/models/taskinstance.py", line 273, in _run_raw_task
    TaskInstance._execute_task_with_callbacks(
  File "/home/airflow/.local/lib/python3.12/site-packages/airflow/models/taskinstance.py", line 3158, in _execute_task_with_callbacks
    result = self._execute_task(context, task_orig)
             ^^^^^^^^^^^^^^^^^^^^^^^^^^^^^^^^^^^^^^
  File "/home/airflow/.local/lib/python3.12/site-packages/airflow/models/taskinstance.py", line 3182, in _execute_task
    return _execute_task(self, context, task_orig)
           ^^^^^^^^^^^^^^^^^^^^^^^^^^^^^^^^^^^^^^^
  File "/home/airflow/.local/lib/python3.12/site-packages/airflow/models/taskinstance.py", line 767, in _execute_task
    result = _execute_callable(context=context, **execute_callable_kwargs)
             ^^^^^^^^^^^^^^^^^^^^^^^^^^^^^^^^^^^^^^^^^^^^^^^^^^^^^^^^^^^^^
  File "/home/airflow/.local/lib/python3.12/site-packages/airflow/models/taskinstance.py", line 733, in _execute_callable
    return ExecutionCallableRunner(
           ^^^^^^^^^^^^^^^^^^^^^^^^
  File "/home/airflow/.local/lib/python3.12/site-packages/airflow/utils/operator_helpers.py", line 252, in run
    return self.func(*args, **kwargs)
           ^^^^^^^^^^^^^^^^^^^^^^^^^^
  File "/home/airflow/.local/lib/python3.12/site-packages/airflow/models/baseoperator.py", line 406, in wrapper
    return func(self, *args, **kwargs)
           ^^^^^^^^^^^^^^^^^^^^^^^^^^^
  File "/home/airflow/.local/lib/python3.12/site-packages/airflow/operators/bash.py", line 249, in execute
    raise AirflowException(
airflow.exceptions.AirflowException: Bash command failed. The command returned a non-zero exit code 2.
[2024-10-24T00:56:41.755+0000] {local_task_job_runner.py:266} INFO - Task exited with return code 1
[2024-10-24T00:56:41.768+0000] {taskinstance.py:3900} INFO - 0 downstream tasks scheduled from follow-on schedule check
[2024-10-24T00:56:41.771+0000] {local_task_job_runner.py:245} INFO - ::endgroup::
