[2024-11-01T00:24:35.180+0000] {local_task_job_runner.py:123} INFO - ::group::Pre task execution logs
[2024-11-01T00:24:35.195+0000] {taskinstance.py:2612} INFO - Dependencies all met for dep_context=non-requeueable deps ti=<TaskInstance: weather_dag.extract_data manual__2024-11-01T00:24:33.423409+00:00 [queued]>
[2024-11-01T00:24:35.203+0000] {taskinstance.py:2612} INFO - Dependencies all met for dep_context=requeueable deps ti=<TaskInstance: weather_dag.extract_data manual__2024-11-01T00:24:33.423409+00:00 [queued]>
[2024-11-01T00:24:35.204+0000] {taskinstance.py:2865} INFO - Starting attempt 1 of 2
[2024-11-01T00:24:35.216+0000] {taskinstance.py:2888} INFO - Executing <Task(BashOperator): extract_data> on 2024-11-01 00:24:33.423409+00:00
[2024-11-01T00:24:35.223+0000] {warnings.py:112} WARNING - /home/***/.local/lib/python3.12/site-packages/***/task/task_runner/standard_task_runner.py:70: DeprecationWarning: This process (pid=79) is multi-threaded, use of fork() may lead to deadlocks in the child.
  pid = os.fork()

[2024-11-01T00:24:35.225+0000] {standard_task_runner.py:104} INFO - Running: ['***', 'tasks', 'run', 'weather_dag', 'extract_data', 'manual__2024-11-01T00:24:33.423409+00:00', '--job-id', '44', '--raw', '--subdir', 'DAGS_FOLDER/Etl_weather.py', '--cfg-path', '/tmp/tmpa2s1obtt']
[2024-11-01T00:24:35.226+0000] {standard_task_runner.py:72} INFO - Started process 82 to run task
[2024-11-01T00:24:35.227+0000] {standard_task_runner.py:105} INFO - Job 44: Subtask extract_data
[2024-11-01T00:24:35.280+0000] {task_command.py:467} INFO - Running <TaskInstance: weather_dag.extract_data manual__2024-11-01T00:24:33.423409+00:00 [running]> on host 915ee6de4e26
[2024-11-01T00:24:35.366+0000] {taskinstance.py:3131} INFO - Exporting env vars: AIRFLOW_CTX_DAG_EMAIL='milo0@gmail.com' AIRFLOW_CTX_DAG_OWNER='milo' AIRFLOW_CTX_DAG_ID='weather_dag' AIRFLOW_CTX_TASK_ID='extract_data' AIRFLOW_CTX_EXECUTION_DATE='2024-11-01T00:24:33.423409+00:00' AIRFLOW_CTX_TRY_NUMBER='1' AIRFLOW_CTX_DAG_RUN_ID='manual__2024-11-01T00:24:33.423409+00:00'
[2024-11-01T00:24:35.367+0000] {taskinstance.py:731} INFO - ::endgroup::
[2024-11-01T00:24:35.382+0000] {subprocess.py:63} INFO - Tmp dir root location: /tmp
[2024-11-01T00:24:35.383+0000] {subprocess.py:75} INFO - Running command: ['/usr/bin/bash', '-c', 'python /opt/***/tmp/extract_data_api.py']
[2024-11-01T00:24:35.394+0000] {subprocess.py:86} INFO - Output:
[2024-11-01T00:24:36.986+0000] {subprocess.py:93} INFO - {'coord': {'lon': -75.5646, 'lat': 6.2529}, 'weather': [{'id': 802, 'main': 'Clouds', 'description': 'scattered clouds', 'icon': '03n'}], 'base': 'stations', 'main': {'temp': 20.21, 'feels_like': 20.64, 'temp_min': 19.77, 'temp_max': 21.07, 'pressure': 1013, 'humidity': 90, 'sea_level': 1013, 'grnd_level': 805}, 'visibility': 10000, 'wind': {'speed': 3.58, 'deg': 60, 'gust': 0}, 'clouds': {'all': 40}, 'dt': 1730420392, 'sys': {'type': 2, 'id': 2084700, 'country': 'CO', 'sunrise': 1730371724, 'sunset': 1730414569}, 'timezone': -18000, 'id': 3674962, 'name': 'Medell√≠n', 'cod': 200}
[2024-11-01T00:24:36.987+0000] {subprocess.py:93} INFO - Traceback (most recent call last):
[2024-11-01T00:24:36.987+0000] {subprocess.py:93} INFO -   File "/opt/***/tmp/extract_data_api.py", line 56, in <module>
[2024-11-01T00:24:36.988+0000] {subprocess.py:93} INFO -     extract_weather_data()
[2024-11-01T00:24:36.989+0000] {subprocess.py:93} INFO -   File "/opt/***/tmp/extract_data_api.py", line 44, in extract_weather_data
[2024-11-01T00:24:36.990+0000] {subprocess.py:93} INFO -     df.to_csv("C:/Users/USUARIO/Desktop/weather_etl/tmp/weather_data.tsv", sep='\t', index=False, mode='w')
[2024-11-01T00:24:36.990+0000] {subprocess.py:93} INFO -   File "/home/***/.local/lib/python3.12/site-packages/pandas/core/generic.py", line 3902, in to_csv
[2024-11-01T00:24:36.992+0000] {subprocess.py:93} INFO -     return DataFrameRenderer(formatter).to_csv(
[2024-11-01T00:24:36.992+0000] {subprocess.py:93} INFO -            ^^^^^^^^^^^^^^^^^^^^^^^^^^^^^^^^^^^^
[2024-11-01T00:24:36.992+0000] {subprocess.py:93} INFO -   File "/home/***/.local/lib/python3.12/site-packages/pandas/io/formats/format.py", line 1152, in to_csv
[2024-11-01T00:24:36.993+0000] {subprocess.py:93} INFO -     csv_formatter.save()
[2024-11-01T00:24:36.993+0000] {subprocess.py:93} INFO -   File "/home/***/.local/lib/python3.12/site-packages/pandas/io/formats/csvs.py", line 247, in save
[2024-11-01T00:24:36.993+0000] {subprocess.py:93} INFO -     with get_handle(
[2024-11-01T00:24:36.994+0000] {subprocess.py:93} INFO -          ^^^^^^^^^^^
[2024-11-01T00:24:36.994+0000] {subprocess.py:93} INFO -   File "/home/***/.local/lib/python3.12/site-packages/pandas/io/common.py", line 739, in get_handle
[2024-11-01T00:24:36.995+0000] {subprocess.py:93} INFO -     check_parent_directory(str(handle))
[2024-11-01T00:24:36.995+0000] {subprocess.py:93} INFO -   File "/home/***/.local/lib/python3.12/site-packages/pandas/io/common.py", line 604, in check_parent_directory
[2024-11-01T00:24:36.995+0000] {subprocess.py:93} INFO -     raise OSError(rf"Cannot save file into a non-existent directory: '{parent}'")
[2024-11-01T00:24:36.996+0000] {subprocess.py:93} INFO - OSError: Cannot save file into a non-existent directory: 'C:/Users/USUARIO/Desktop/weather_etl/tmp'
[2024-11-01T00:24:37.110+0000] {subprocess.py:97} INFO - Command exited with return code 1
[2024-11-01T00:24:37.120+0000] {taskinstance.py:3310} ERROR - Task failed with exception
Traceback (most recent call last):
  File "/home/airflow/.local/lib/python3.12/site-packages/airflow/models/taskinstance.py", line 767, in _execute_task
    result = _execute_callable(context=context, **execute_callable_kwargs)
             ^^^^^^^^^^^^^^^^^^^^^^^^^^^^^^^^^^^^^^^^^^^^^^^^^^^^^^^^^^^^^
  File "/home/airflow/.local/lib/python3.12/site-packages/airflow/models/taskinstance.py", line 733, in _execute_callable
    return ExecutionCallableRunner(
           ^^^^^^^^^^^^^^^^^^^^^^^^
  File "/home/airflow/.local/lib/python3.12/site-packages/airflow/utils/operator_helpers.py", line 252, in run
    return self.func(*args, **kwargs)
           ^^^^^^^^^^^^^^^^^^^^^^^^^^
  File "/home/airflow/.local/lib/python3.12/site-packages/airflow/models/baseoperator.py", line 406, in wrapper
    return func(self, *args, **kwargs)
           ^^^^^^^^^^^^^^^^^^^^^^^^^^^
  File "/home/airflow/.local/lib/python3.12/site-packages/airflow/operators/bash.py", line 249, in execute
    raise AirflowException(
airflow.exceptions.AirflowException: Bash command failed. The command returned a non-zero exit code 1.
[2024-11-01T00:24:37.131+0000] {taskinstance.py:1225} INFO - Marking task as UP_FOR_RETRY. dag_id=weather_dag, task_id=extract_data, run_id=manual__2024-11-01T00:24:33.423409+00:00, execution_date=20241101T002433, start_date=20241101T002435, end_date=20241101T002437
[2024-11-01T00:24:37.151+0000] {taskinstance.py:340} INFO - ::group::Post task execution logs
[2024-11-01T00:24:37.152+0000] {standard_task_runner.py:124} ERROR - Failed to execute job 44 for task extract_data (Bash command failed. The command returned a non-zero exit code 1.; 82)
Traceback (most recent call last):
  File "/home/airflow/.local/lib/python3.12/site-packages/airflow/task/task_runner/standard_task_runner.py", line 117, in _start_by_fork
    ret = args.func(args, dag=self.dag)
          ^^^^^^^^^^^^^^^^^^^^^^^^^^^^^
  File "/home/airflow/.local/lib/python3.12/site-packages/airflow/cli/cli_config.py", line 49, in command
    return func(*args, **kwargs)
           ^^^^^^^^^^^^^^^^^^^^^
  File "/home/airflow/.local/lib/python3.12/site-packages/airflow/utils/cli.py", line 115, in wrapper
    return f(*args, **kwargs)
           ^^^^^^^^^^^^^^^^^^
  File "/home/airflow/.local/lib/python3.12/site-packages/airflow/cli/commands/task_command.py", line 483, in task_run
    task_return_code = _run_task_by_selected_method(args, _dag, ti)
                       ^^^^^^^^^^^^^^^^^^^^^^^^^^^^^^^^^^^^^^^^^^^^
  File "/home/airflow/.local/lib/python3.12/site-packages/airflow/cli/commands/task_command.py", line 256, in _run_task_by_selected_method
    return _run_raw_task(args, ti)
           ^^^^^^^^^^^^^^^^^^^^^^^
  File "/home/airflow/.local/lib/python3.12/site-packages/airflow/cli/commands/task_command.py", line 341, in _run_raw_task
    return ti._run_raw_task(
           ^^^^^^^^^^^^^^^^^
  File "/home/airflow/.local/lib/python3.12/site-packages/airflow/utils/session.py", line 97, in wrapper
    return func(*args, session=session, **kwargs)
           ^^^^^^^^^^^^^^^^^^^^^^^^^^^^^^^^^^^^^^
  File "/home/airflow/.local/lib/python3.12/site-packages/airflow/models/taskinstance.py", line 3004, in _run_raw_task
    return _run_raw_task(
           ^^^^^^^^^^^^^^
  File "/home/airflow/.local/lib/python3.12/site-packages/airflow/models/taskinstance.py", line 273, in _run_raw_task
    TaskInstance._execute_task_with_callbacks(
  File "/home/airflow/.local/lib/python3.12/site-packages/airflow/models/taskinstance.py", line 3158, in _execute_task_with_callbacks
    result = self._execute_task(context, task_orig)
             ^^^^^^^^^^^^^^^^^^^^^^^^^^^^^^^^^^^^^^
  File "/home/airflow/.local/lib/python3.12/site-packages/airflow/models/taskinstance.py", line 3182, in _execute_task
    return _execute_task(self, context, task_orig)
           ^^^^^^^^^^^^^^^^^^^^^^^^^^^^^^^^^^^^^^^
  File "/home/airflow/.local/lib/python3.12/site-packages/airflow/models/taskinstance.py", line 767, in _execute_task
    result = _execute_callable(context=context, **execute_callable_kwargs)
             ^^^^^^^^^^^^^^^^^^^^^^^^^^^^^^^^^^^^^^^^^^^^^^^^^^^^^^^^^^^^^
  File "/home/airflow/.local/lib/python3.12/site-packages/airflow/models/taskinstance.py", line 733, in _execute_callable
    return ExecutionCallableRunner(
           ^^^^^^^^^^^^^^^^^^^^^^^^
  File "/home/airflow/.local/lib/python3.12/site-packages/airflow/utils/operator_helpers.py", line 252, in run
    return self.func(*args, **kwargs)
           ^^^^^^^^^^^^^^^^^^^^^^^^^^
  File "/home/airflow/.local/lib/python3.12/site-packages/airflow/models/baseoperator.py", line 406, in wrapper
    return func(self, *args, **kwargs)
           ^^^^^^^^^^^^^^^^^^^^^^^^^^^
  File "/home/airflow/.local/lib/python3.12/site-packages/airflow/operators/bash.py", line 249, in execute
    raise AirflowException(
airflow.exceptions.AirflowException: Bash command failed. The command returned a non-zero exit code 1.
[2024-11-01T00:24:37.171+0000] {local_task_job_runner.py:266} INFO - Task exited with return code 1
[2024-11-01T00:24:37.180+0000] {warnings.py:112} WARNING - /home/***/.local/lib/python3.12/site-packages/***/models/baseoperator.py:1378: AirflowProviderDeprecationWarning: Call to deprecated class PostgresOperator. (Please use `***.providers.common.sql.operators.sql.SQLExecuteQueryOperator`.Also, you can provide `hook_params={'schema': <database>}`.)
  result = cls.__new__(cls)

[2024-11-01T00:24:37.192+0000] {taskinstance.py:3900} INFO - 0 downstream tasks scheduled from follow-on schedule check
[2024-11-01T00:24:37.194+0000] {local_task_job_runner.py:245} INFO - ::endgroup::
