[2024-10-31T02:40:58.700+0000] {local_task_job_runner.py:123} INFO - ::group::Pre task execution logs
[2024-10-31T02:40:58.713+0000] {taskinstance.py:2612} INFO - Dependencies all met for dep_context=non-requeueable deps ti=<TaskInstance: weather_dag.extract_data manual__2024-10-31T02:09:01.852271+00:00 [queued]>
[2024-10-31T02:40:58.722+0000] {taskinstance.py:2612} INFO - Dependencies all met for dep_context=requeueable deps ti=<TaskInstance: weather_dag.extract_data manual__2024-10-31T02:09:01.852271+00:00 [queued]>
[2024-10-31T02:40:58.722+0000] {taskinstance.py:2865} INFO - Starting attempt 2 of 2
[2024-10-31T02:40:58.735+0000] {taskinstance.py:2888} INFO - Executing <Task(BashOperator): extract_data> on 2024-10-31 02:09:01.852271+00:00
[2024-10-31T02:40:58.741+0000] {warnings.py:112} WARNING - /home/***/.local/lib/python3.12/site-packages/***/task/task_runner/standard_task_runner.py:70: DeprecationWarning: This process (pid=93) is multi-threaded, use of fork() may lead to deadlocks in the child.
  pid = os.fork()

[2024-10-31T02:40:58.744+0000] {standard_task_runner.py:72} INFO - Started process 95 to run task
[2024-10-31T02:40:58.745+0000] {standard_task_runner.py:104} INFO - Running: ['***', 'tasks', 'run', 'weather_dag', 'extract_data', 'manual__2024-10-31T02:09:01.852271+00:00', '--job-id', '40', '--raw', '--subdir', 'DAGS_FOLDER/Etl_weather.py', '--cfg-path', '/tmp/tmpiuuabvm8']
[2024-10-31T02:40:58.746+0000] {standard_task_runner.py:105} INFO - Job 40: Subtask extract_data
[2024-10-31T02:40:58.785+0000] {task_command.py:467} INFO - Running <TaskInstance: weather_dag.extract_data manual__2024-10-31T02:09:01.852271+00:00 [running]> on host 915ee6de4e26
[2024-10-31T02:40:58.855+0000] {taskinstance.py:3131} INFO - Exporting env vars: AIRFLOW_CTX_DAG_EMAIL='milo0@gmail.com' AIRFLOW_CTX_DAG_OWNER='milo' AIRFLOW_CTX_DAG_ID='weather_dag' AIRFLOW_CTX_TASK_ID='extract_data' AIRFLOW_CTX_EXECUTION_DATE='2024-10-31T02:09:01.852271+00:00' AIRFLOW_CTX_TRY_NUMBER='2' AIRFLOW_CTX_DAG_RUN_ID='manual__2024-10-31T02:09:01.852271+00:00'
[2024-10-31T02:40:58.856+0000] {taskinstance.py:731} INFO - ::endgroup::
[2024-10-31T02:40:58.885+0000] {subprocess.py:63} INFO - Tmp dir root location: /tmp
[2024-10-31T02:40:58.886+0000] {subprocess.py:75} INFO - Running command: ['/usr/bin/bash', '-c', 'python /opt/***/plugins/tmp/extract_data_api.py']
[2024-10-31T02:40:58.894+0000] {subprocess.py:86} INFO - Output:
[2024-10-31T02:40:58.921+0000] {subprocess.py:93} INFO - python: can't open file '/opt/***/plugins/tmp/extract_data_api.py': [Errno 2] No such file or directory
[2024-10-31T02:40:58.923+0000] {subprocess.py:97} INFO - Command exited with return code 2
[2024-10-31T02:40:58.931+0000] {taskinstance.py:3310} ERROR - Task failed with exception
Traceback (most recent call last):
  File "/home/airflow/.local/lib/python3.12/site-packages/airflow/models/taskinstance.py", line 767, in _execute_task
    result = _execute_callable(context=context, **execute_callable_kwargs)
             ^^^^^^^^^^^^^^^^^^^^^^^^^^^^^^^^^^^^^^^^^^^^^^^^^^^^^^^^^^^^^
  File "/home/airflow/.local/lib/python3.12/site-packages/airflow/models/taskinstance.py", line 733, in _execute_callable
    return ExecutionCallableRunner(
           ^^^^^^^^^^^^^^^^^^^^^^^^
  File "/home/airflow/.local/lib/python3.12/site-packages/airflow/utils/operator_helpers.py", line 252, in run
    return self.func(*args, **kwargs)
           ^^^^^^^^^^^^^^^^^^^^^^^^^^
  File "/home/airflow/.local/lib/python3.12/site-packages/airflow/models/baseoperator.py", line 406, in wrapper
    return func(self, *args, **kwargs)
           ^^^^^^^^^^^^^^^^^^^^^^^^^^^
  File "/home/airflow/.local/lib/python3.12/site-packages/airflow/operators/bash.py", line 249, in execute
    raise AirflowException(
airflow.exceptions.AirflowException: Bash command failed. The command returned a non-zero exit code 2.
[2024-10-31T02:40:58.935+0000] {taskinstance.py:1225} INFO - Marking task as FAILED. dag_id=weather_dag, task_id=extract_data, run_id=manual__2024-10-31T02:09:01.852271+00:00, execution_date=20241031T020901, start_date=20241031T024058, end_date=20241031T024058
[2024-10-31T02:40:58.945+0000] {taskinstance.py:340} INFO - ::group::Post task execution logs
[2024-10-31T02:40:58.946+0000] {standard_task_runner.py:124} ERROR - Failed to execute job 40 for task extract_data (Bash command failed. The command returned a non-zero exit code 2.; 95)
Traceback (most recent call last):
  File "/home/airflow/.local/lib/python3.12/site-packages/airflow/task/task_runner/standard_task_runner.py", line 117, in _start_by_fork
    ret = args.func(args, dag=self.dag)
          ^^^^^^^^^^^^^^^^^^^^^^^^^^^^^
  File "/home/airflow/.local/lib/python3.12/site-packages/airflow/cli/cli_config.py", line 49, in command
    return func(*args, **kwargs)
           ^^^^^^^^^^^^^^^^^^^^^
  File "/home/airflow/.local/lib/python3.12/site-packages/airflow/utils/cli.py", line 115, in wrapper
    return f(*args, **kwargs)
           ^^^^^^^^^^^^^^^^^^
  File "/home/airflow/.local/lib/python3.12/site-packages/airflow/cli/commands/task_command.py", line 483, in task_run
    task_return_code = _run_task_by_selected_method(args, _dag, ti)
                       ^^^^^^^^^^^^^^^^^^^^^^^^^^^^^^^^^^^^^^^^^^^^
  File "/home/airflow/.local/lib/python3.12/site-packages/airflow/cli/commands/task_command.py", line 256, in _run_task_by_selected_method
    return _run_raw_task(args, ti)
           ^^^^^^^^^^^^^^^^^^^^^^^
  File "/home/airflow/.local/lib/python3.12/site-packages/airflow/cli/commands/task_command.py", line 341, in _run_raw_task
    return ti._run_raw_task(
           ^^^^^^^^^^^^^^^^^
  File "/home/airflow/.local/lib/python3.12/site-packages/airflow/utils/session.py", line 97, in wrapper
    return func(*args, session=session, **kwargs)
           ^^^^^^^^^^^^^^^^^^^^^^^^^^^^^^^^^^^^^^
  File "/home/airflow/.local/lib/python3.12/site-packages/airflow/models/taskinstance.py", line 3004, in _run_raw_task
    return _run_raw_task(
           ^^^^^^^^^^^^^^
  File "/home/airflow/.local/lib/python3.12/site-packages/airflow/models/taskinstance.py", line 273, in _run_raw_task
    TaskInstance._execute_task_with_callbacks(
  File "/home/airflow/.local/lib/python3.12/site-packages/airflow/models/taskinstance.py", line 3158, in _execute_task_with_callbacks
    result = self._execute_task(context, task_orig)
             ^^^^^^^^^^^^^^^^^^^^^^^^^^^^^^^^^^^^^^
  File "/home/airflow/.local/lib/python3.12/site-packages/airflow/models/taskinstance.py", line 3182, in _execute_task
    return _execute_task(self, context, task_orig)
           ^^^^^^^^^^^^^^^^^^^^^^^^^^^^^^^^^^^^^^^
  File "/home/airflow/.local/lib/python3.12/site-packages/airflow/models/taskinstance.py", line 767, in _execute_task
    result = _execute_callable(context=context, **execute_callable_kwargs)
             ^^^^^^^^^^^^^^^^^^^^^^^^^^^^^^^^^^^^^^^^^^^^^^^^^^^^^^^^^^^^^
  File "/home/airflow/.local/lib/python3.12/site-packages/airflow/models/taskinstance.py", line 733, in _execute_callable
    return ExecutionCallableRunner(
           ^^^^^^^^^^^^^^^^^^^^^^^^
  File "/home/airflow/.local/lib/python3.12/site-packages/airflow/utils/operator_helpers.py", line 252, in run
    return self.func(*args, **kwargs)
           ^^^^^^^^^^^^^^^^^^^^^^^^^^
  File "/home/airflow/.local/lib/python3.12/site-packages/airflow/models/baseoperator.py", line 406, in wrapper
    return func(self, *args, **kwargs)
           ^^^^^^^^^^^^^^^^^^^^^^^^^^^
  File "/home/airflow/.local/lib/python3.12/site-packages/airflow/operators/bash.py", line 249, in execute
    raise AirflowException(
airflow.exceptions.AirflowException: Bash command failed. The command returned a non-zero exit code 2.
[2024-10-31T02:40:58.961+0000] {local_task_job_runner.py:266} INFO - Task exited with return code 1
[2024-10-31T02:40:58.968+0000] {warnings.py:112} WARNING - /home/***/.local/lib/python3.12/site-packages/***/models/baseoperator.py:1378: AirflowProviderDeprecationWarning: Call to deprecated class PostgresOperator. (Please use `***.providers.common.sql.operators.sql.SQLExecuteQueryOperator`.Also, you can provide `hook_params={'schema': <database>}`.)
  result = cls.__new__(cls)

[2024-10-31T02:40:58.978+0000] {taskinstance.py:3900} INFO - 0 downstream tasks scheduled from follow-on schedule check
[2024-10-31T02:40:58.982+0000] {local_task_job_runner.py:245} INFO - ::endgroup::
